Workbook
Name FYAPR: AAZ!$E$10:$E$10
Name FYAPR: Annual!$D$10:$D$10
Name FYAPR: BWB!$E$10:$E$20
Name FYAPR: 'BWB(MDOT)'!$E$10:$E$20
Name FYAPR: 'BWB-FBCL'!$E$10:$E$20
Name FYAPR: 'Compiled-YTD'!$AH$10:$AH$20
Name FYAPR: DWT!$E$10:$E$20
Name FYAPR: GHIB!$E$10:$E$20
Name FYAPR: IBA!$E$10:$E$20
Name FYAPR: LQB!$E$10:$E$20
Name FYAPR: OGB!$E$10:$E$20
Name FYAPR: PB!$E$10:$E$20
Name FYAPR: RBW!$E$10:$E$20
Name FYAPR: SIBC!$E$10:$E$20
Name FYAPR: TIBA!$E$10:$E$20
Name FYAPR: WPB!$E$10:$E$20
Name FYAPR: AMB!$E$10:$E$20
Name FYFEB: AAZ!$E$10:$E$10
Name FYFEB: Annual!$D$10:$D$10
Name FYFEB: BWB!$E$10:$E$20
Name FYFEB: 'BWB(MDOT)'!$E$10:$E$20
Name FYFEB: 'BWB-FBCL'!$E$10:$E$20
Name FYFEB: 'Compiled-YTD'!$AH$10:$AH$20
Name FYFEB: DWT!$E$10:$E$20
Name FYFEB: GHIB!$E$10:$E$20
Name FYFEB: IBA!$E$10:$E$20
Name FYFEB: LQB!$E$10:$E$20
Name FYFEB: OGB!$E$10:$E$20
Name FYFEB: PB!$E$10:$E$20
Name FYFEB: RBW!$E$10:$E$20
Name FYFEB: SIBC!$E$10:$E$20
Name FYFEB: TIBA!$E$10:$E$20
Name FYFEB: WPB!$E$10:$E$20
Name FYFEB: AMB!$E$10:$E$20
Name FYJAN: AAZ!$E$10:$E$10
Name FYJAN: Annual!$D$10:$D$10
Name FYJAN: BWB!$E$10:$E$20
Name FYJAN: 'BWB(MDOT)'!$E$10:$E$20
Name FYJAN: 'BWB-FBCL'!$E$10:$E$20
Name FYJAN: 'Compiled-YTD'!$AH$10:$AH$20
Name FYJAN: DWT!$E$10:$E$20
Name FYJAN: GHIB!$E$10:$E$20
Name FYJAN: IBA!$E$10:$E$20
Name FYJAN: LQB!$E$10:$E$20
Name FYJAN: OGB!$E$10:$E$20
Name FYJAN: PB!$E$10:$E$20
Name FYJAN: RBW!$E$10:$E$20
Name FYJAN: SIBC!$E$10:$E$20
Name FYJAN: TIBA!$E$10:$E$20
Name FYJAN: WPB!$E$10:$E$20
Name FYJAN: AMB!$E$10:$E$20
Name FYMAR: AAZ!$E$10:$E$10
Name FYMAR: Annual!$D$10:$D$10
Name FYMAR: BWB!$E$10:$E$20
Name FYMAR: 'BWB(MDOT)'!$E$10:$E$20
Name FYMAR: 'BWB-FBCL'!$E$10:$E$20
Name FYMAR: 'Compiled-YTD'!$AH$10:$AH$20
Name FYMAR: DWT!$E$10:$E$20
Name FYMAR: GHIB!$E$10:$E$20
Name FYMAR: IBA!$E$10:$E$20

Sheet Dashboard
B2: BRIDGE AND TUNNEL OPERATORS ASSOCIATION (BTOA)
B3: Ontario Border Crossings with Michigan & New York | F3: BTOA DASHBOARD
I4: Traffic Month Ending | N4: Traffic Year to Date
B5: Instructions for YEAR to YEAR traffic comparisons | G5: Individual Crossings | I5: =+$C$16 -> August | N5: =CONCATENATE("Month Ending ",C16) -> Month Ending August | S5: YEARS | U5: MONTH
F6: CROSSING LIST | G6: Tab Names | I6: =+$C$13 -> 2025 | J6: =+$C$14 -> 2026 | L6: Change | N6: =+$C$13 -> 2025 | O6: =+$C$14 -> 2026 | Q6: Change | S6: (Validation List) | U6: (Validation List)
A7: 1 | B7: Select the years to compare below in cell C8 and C9, respectively. | F7: Aazhogan Bridge | G7: AAZ | I7: =SUMIFS(Traffic!FD:FD,Traffic!$B:$B,Dashboard!$G7,Traffic!$CY:$CY,Dashboard!$F$21) -> 26263 | J7: =SUMIFS(Traffic!FE:FE,Traffic!$B:$B,Dashboard!$G7,Traffic!$CY:$CY,Dashboard!$F$21) -> 26602 | K7: =IF(L7<0,-1,IF(L7=0,0,1)) -> 1 | L7: =SUMIFS(Traffic!FG:FG,Traffic!$B:$B,Dashboard!$G7,Traffic!$CY:$CY,Dashboard!$F$21) -> 0.012907893 | N7: =SUMIFS(Traffic!FI:FI,Traffic!$B:$B,Dashboard!$G7,Traffic!$CY:$CY,Dashboard!$F$21) -> 155534 | O7: =SUMIFS(Traffic!FJ:FJ,Traffic!$B:$B,Dashboard!$G7,Traffic!$CY:$CY,Dashboard!$F$21) -> 159252 | P7: =IF(Q7<0,-1,IF(Q7=0,0,1)) -> 1 | Q7: =SUMIFS(Traffic!FL:FL,Traffic!$B:$B,Dashboard!$G7,Traffic!$CY:$CY,Dashboard!$F$21) -> 0.023904741 | S7: 2006 | U7: January
A8: 2 | B8: Data presented by crossing, on the "Traffic" tab. | F8: Ambassador Bridge | G8: AMB | I8: =SUMIFS(Traffic!FD:FD,Traffic!$B:$B,Dashboard!$G8,Traffic!$CY:$CY,Dashboard!$F$21) -> 492944 | J8: =SUMIFS(Traffic!FE:FE,Traffic!$B:$B,Dashboard!$G8,Traffic!$CY:$CY,Dashboard!$F$21) -> 345445 | K8: =IF(L8<0,-1,IF(L8=0,0,1)) -> -1 | L8: =SUMIFS(Traffic!FG:FG,Traffic!$B:$B,Dashboard!$G8,Traffic!$CY:$CY,Dashboard!$F$21) -> -0.2992206 | N8: =SUMIFS(Traffic!FI:FI,Traffic!$B:$B,Dashboard!$G8,Traffic!$CY:$CY,Dashboard!$F$21) -> 3616013 | O8: =SUMIFS(Traffic!FJ:FJ,Traffic!$B:$B,Dashboard!$G8,Traffic!$CY:$CY,Dashboard!$F$21) -> 3615317 | P8: =IF(Q8<0,-1,IF(Q8=0,0,1)) -> -1 | Q8: =SUMIFS(Traffic!FL:FL,Traffic!$B:$B,Dashboard!$G8,Traffic!$CY:$CY,Dashboard!$F$21) -> -0.00019247718 | S8: 2007 | U8: February
A9: 3 | B9: Traffic data for individual crossings on tabs, per "Crossing List". | F9: Blue Water Bridge | G9: BWB | I9: =SUMIFS(Traffic!FD:FD,Traffic!$B:$B,Dashboard!$G9,Traffic!$CY:$CY,Dashboard!$F$21) -> 372862 | J9: =SUMIFS(Traffic!FE:FE,Traffic!$B:$B,Dashboard!$G9,Traffic!$CY:$CY,Dashboard!$F$21) -> 333986 | K9: =IF(L9<0,-1,IF(L9=0,0,1)) -> -1 | L9: =SUMIFS(Traffic!FG:FG,Traffic!$B:$B,Dashboard!$G9,Traffic!$CY:$CY,Dashboard!$F$21) -> -0.10426378 | N9: =SUMIFS(Traffic!FI:FI,Traffic!$B:$B,Dashboard!$G9,Traffic!$CY:$CY,Dashboard!$F$21) -> 2575009 | O9: =SUMIFS(Traffic!FJ:FJ,Traffic!$B:$B,Dashboard!$G9,Traffic!$CY:$CY,Dashboard!$F$21) -> 2411385 | P9: =IF(Q9<0,-1,IF(Q9=0,0,1)) -> -1 | Q9: =SUMIFS(Traffic!FL:FL,Traffic!$B:$B,Dashboard!$G9,Traffic!$CY:$CY,Dashboard!$F$21) -> -0.063543079 | S9: 2008 | U9: March
A10: 4 | B10: Total annualized BTOA Traffic on "Annual" Tab. | F10: Detroit-Windsor Tunnel | G10: DWT | I10: =SUMIFS(Traffic!FD:FD,Traffic!$B:$B,Dashboard!$G10,Traffic!$CY:$CY,Dashboard!$F$21) -> 343114 | J10: =SUMIFS(Traffic!FE:FE,Traffic!$B:$B,Dashboard!$G10,Traffic!$CY:$CY,Dashboard!$F$21) -> 282880 | K10: =IF(L10<0,-1,IF(L10=0,0,1)) -> -1 | L10: =SUMIFS(Traffic!FG:FG,Traffic!$B:$B,Dashboard!$G10,Traffic!$CY:$CY,Dashboard!$F$21) -> -0.17555098 | N10: =SUMIFS(Traffic!FI:FI,Traffic!$B:$B,Dashboard!$G10,Traffic!$CY:$CY,Dashboard!$F$21) -> 2496067 | O10: =SUMIFS(Traffic!FJ:FJ,Traffic!$B:$B,Dashboard!$G10,Traffic!$CY:$CY,Dashboard!$F$21) -> 2479935 | P10: =IF(Q10<0,-1,IF(Q10=0,0,1)) -> -1 | Q10: =SUMIFS(Traffic!FL:FL,Traffic!$B:$B,Dashboard!$G10,Traffic!$CY:$CY,Dashboard!$F$21) -> -0.0064629675 | S10: 2009 | U10: April
F11: Gordie Howe International Bridge | G11: GHIB | I11: =SUMIFS(Traffic!FD:FD,Traffic!$B:$B,Dashboard!$G11,Traffic!$CY:$CY,Dashboard!$F$21) -> 0 | J11: =SUMIFS(Traffic!FE:FE,Traffic!$B:$B,Dashboard!$G11,Traffic!$CY:$CY,Dashboard!$F$21) -> 343507 | K11: =IF(L11<0,-1,IF(L11=0,0,1)) -> 1 | L11: =SUMIFS(Traffic!FG:FG,Traffic!$B:$B,Dashboard!$G11,Traffic!$CY:$CY,Dashboard!$F$21) -> 1 | N11: =SUMIFS(Traffic!FI:FI,Traffic!$B:$B,Dashboard!$G11,Traffic!$CY:$CY,Dashboard!$F$21) -> 0 | O11: =SUMIFS(Traffic!FJ:FJ,Traffic!$B:$B,Dashboard!$G11,Traffic!$CY:$CY,Dashboard!$F$21) -> 395660 | P11: =IF(Q11<0,-1,IF(Q11=0,0,1)) -> 1 | Q11: =SUMIFS(Traffic!FL:FL,Traffic!$B:$B,Dashboard!$G11,Traffic!$CY:$CY,Dashboard!$F$21) -> 1 | S11: 2010 | U11: May
B12: Years to Compare | F12: Ogdensburg Bridge | G12: OGB | I12: =SUMIFS(Traffic!FD:FD,Traffic!$B:$B,Dashboard!$G12,Traffic!$CY:$CY,Dashboard!$F$21) -> 47584 | J12: =SUMIFS(Traffic!FE:FE,Traffic!$B:$B,Dashboard!$G12,Traffic!$CY:$CY,Dashboard!$F$21) -> 52943 | K12: =IF(L12<0,-1,IF(L12=0,0,1)) -> 1 | L12: =SUMIFS(Traffic!FG:FG,Traffic!$B:$B,Dashboard!$G12,Traffic!$CY:$CY,Dashboard!$F$21) -> 0.11262189 | N12: =SUMIFS(Traffic!FI:FI,Traffic!$B:$B,Dashboard!$G12,Traffic!$CY:$CY,Dashboard!$F$21) -> 303626 | O12: =SUMIFS(Traffic!FJ:FJ,Traffic!$B:$B,Dashboard!$G12,Traffic!$CY:$CY,Dashboard!$F$21) -> 316801 | P12: =IF(Q12<0,-1,IF(Q12=0,0,1)) -> 1 | Q12: =SUMIFS(Traffic!FL:FL,Traffic!$B:$B,Dashboard!$G12,Traffic!$CY:$CY,Dashboard!$F$21) -> 0.0433922 | S12: 2011 | U12: June
B13: Prior Year | C13: 2025 | D13: Select first year to compare | F13: Peace Bridge | G13: PB | I13: =SUMIFS(Traffic!FD:FD,Traffic!$B:$B,Dashboard!$G13,Traffic!$CY:$CY,Dashboard!$F$21) -> 477548 | J13: =SUMIFS(Traffic!FE:FE,Traffic!$B:$B,Dashboard!$G13,Traffic!$CY:$CY,Dashboard!$F$21) -> 473729 | K13: =IF(L13<0,-1,IF(L13=0,0,1)) -> -1 | L13: =SUMIFS(Traffic!FG:FG,Traffic!$B:$B,Dashboard!$G13,Traffic!$CY:$CY,Dashboard!$F$21) -> -0.0079971019 | N13: =SUMIFS(Traffic!FI:FI,Traffic!$B:$B,Dashboard!$G13,Traffic!$CY:$CY,Dashboard!$F$21) -> 2866364 | O13: =SUMIFS(Traffic!FJ:FJ,Traffic!$B:$B,Dashboard!$G13,Traffic!$CY:$CY,Dashboard!$F$21) -> 2894078 | P13: =IF(Q13<0,-1,IF(Q13=0,0,1)) -> 1 | Q13: =SUMIFS(Traffic!FL:FL,Traffic!$B:$B,Dashboard!$G13,Traffic!$CY:$CY,Dashboard!$F$21) -> 0.0096686953 | S13: 2012 | U13: July
B14: Current Year | C14: 2026 | D14: Select second year to compare | F14: Sault Ste. Marie Bridge Bridge Authority | G14: IBA | I14: =SUMIFS(Traffic!FD:FD,Traffic!$B:$B,Dashboard!$G14,Traffic!$CY:$CY,Dashboard!$F$21) -> 96565 | J14: =SUMIFS(Traffic!FE:FE,Traffic!$B:$B,Dashboard!$G14,Traffic!$CY:$CY,Dashboard!$F$21) -> 99731 | K14: =IF(L14<0,-1,IF(L14=0,0,1)) -> 1 | L14: =SUMIFS(Traffic!FG:FG,Traffic!$B:$B,Dashboard!$G14,Traffic!$CY:$CY,Dashboard!$F$21) -> 0.032786206 | N14: =SUMIFS(Traffic!FI:FI,Traffic!$B:$B,Dashboard!$G14,Traffic!$CY:$CY,Dashboard!$F$21) -> 566216 | O14: =SUMIFS(Traffic!FJ:FJ,Traffic!$B:$B,Dashboard!$G14,Traffic!$CY:$CY,Dashboard!$F$21) -> 573998 | P14: =IF(Q14<0,-1,IF(Q14=0,0,1)) -> 1 | Q14: =SUMIFS(Traffic!FL:FL,Traffic!$B:$B,Dashboard!$G14,Traffic!$CY:$CY,Dashboard!$F$21) -> 0.013743872 | S14: 2013 | U14: August
F15: Seaway International Bridge | G15: SIBC | I15: =SUMIFS(Traffic!FD:FD,Traffic!$B:$B,Dashboard!$G15,Traffic!$CY:$CY,Dashboard!$F$21) -> 211605 | J15: =SUMIFS(Traffic!FE:FE,Traffic!$B:$B,Dashboard!$G15,Traffic!$CY:$CY,Dashboard!$F$21) -> 222135 | K15: =IF(L15<0,-1,IF(L15=0,0,1)) -> 1 | L15: =SUMIFS(Traffic!FG:FG,Traffic!$B:$B,Dashboard!$G15,Traffic!$CY:$CY,Dashboard!$F$21) -> 0.049762529 | N15: =SUMIFS(Traffic!FI:FI,Traffic!$B:$B,Dashboard!$G15,Traffic!$CY:$CY,Dashboard!$F$21) -> 1665834 | O15: =SUMIFS(Traffic!FJ:FJ,Traffic!$B:$B,Dashboard!$G15,Traffic!$CY:$CY,Dashboard!$F$21) -> 1691189 | P15: =IF(Q15<0,-1,IF(Q15=0,0,1)) -> 1 | Q15: =SUMIFS(Traffic!FL:FL,Traffic!$B:$B,Dashboard!$G15,Traffic!$CY:$CY,Dashboard!$F$21) -> 0.015220604 | S15: 2014 | U15: September
B16: Current Month | C16: August | D16: Select month | F16: Thousand Islands Bridge | G16: TIBA | I16: =SUMIFS(Traffic!FD:FD,Traffic!$B:$B,Dashboard!$G16,Traffic!$CY:$CY,Dashboard!$F$21) -> 210693 | J16: =SUMIFS(Traffic!FE:FE,Traffic!$B:$B,Dashboard!$G16,Traffic!$CY:$CY,Dashboard!$F$21) -> 213798 | K16: =IF(L16<0,-1,IF(L16=0,0,1)) -> 1 | L16: =SUMIFS(Traffic!FG:FG,Traffic!$B:$B,Dashboard!$G16,Traffic!$CY:$CY,Dashboard!$F$21) -> 0.014737082 | N16: =SUMIFS(Traffic!FI:FI,Traffic!$B:$B,Dashboard!$G16,Traffic!$CY:$CY,Dashboard!$F$21) -> 1153828 | O16: =SUMIFS(Traffic!FJ:FJ,Traffic!$B:$B,Dashboard!$G16,Traffic!$CY:$CY,Dashboard!$F$21) -> 1144838 | P16: =IF(Q16<0,-1,IF(Q16=0,0,1)) -> -1 | Q16: =SUMIFS(Traffic!FL:FL,Traffic!$B:$B,Dashboard!$G16,Traffic!$CY:$CY,Dashboard!$F$21) -> -0.0077914559 | S16: 2015 | U16: October
F17: Lewiston-Queenston Bridge | G17: LQB | I17: =SUMIFS(Traffic!FD:FD,Traffic!$B:$B,Dashboard!$G17,Traffic!$CY:$CY,Dashboard!$F$21) -> 314803 | J17: =SUMIFS(Traffic!FE:FE,Traffic!$B:$B,Dashboard!$G17,Traffic!$CY:$CY,Dashboard!$F$21) -> 343000 | K17: =IF(L17<0,-1,IF(L17=0,0,1)) -> 1 | L17: =SUMIFS(Traffic!FG:FG,Traffic!$B:$B,Dashboard!$G17,Traffic!$CY:$CY,Dashboard!$F$21) -> 0.089570303 | N17: =SUMIFS(Traffic!FI:FI,Traffic!$B:$B,Dashboard!$G17,Traffic!$CY:$CY,Dashboard!$F$21) -> 1862494 | O17: =SUMIFS(Traffic!FJ:FJ,Traffic!$B:$B,Dashboard!$G17,Traffic!$CY:$CY,Dashboard!$F$21) -> 1960999 | P17: =IF(Q17<0,-1,IF(Q17=0,0,1)) -> 1 | Q17: =SUMIFS(Traffic!FL:FL,Traffic!$B:$B,Dashboard!$G17,Traffic!$CY:$CY,Dashboard!$F$21) -> 0.052888761 | S17: 2016 | U17: November
B18: Graph | F18: Rainbow Bridge | G18: RBW | I18: =SUMIFS(Traffic!FD:FD,Traffic!$B:$B,Dashboard!$G18,Traffic!$CY:$CY,Dashboard!$F$21) -> 216230 | J18: =SUMIFS(Traffic!FE:FE,Traffic!$B:$B,Dashboard!$G18,Traffic!$CY:$CY,Dashboard!$F$21) -> 217147 | K18: =IF(L18<0,-1,IF(L18=0,0,1)) -> 1 | L18: =SUMIFS(Traffic!FG:FG,Traffic!$B:$B,Dashboard!$G18,Traffic!$CY:$CY,Dashboard!$F$21) -> 0.0042408546 | N18: =SUMIFS(Traffic!FI:FI,Traffic!$B:$B,Dashboard!$G18,Traffic!$CY:$CY,Dashboard!$F$21) -> 1168850 | O18: =SUMIFS(Traffic!FJ:FJ,Traffic!$B:$B,Dashboard!$G18,Traffic!$CY:$CY,Dashboard!$F$21) -> 1187070 | P18: =IF(Q18<0,-1,IF(Q18=0,0,1)) -> 1 | Q18: =SUMIFS(Traffic!FL:FL,Traffic!$B:$B,Dashboard!$G18,Traffic!$CY:$CY,Dashboard!$F$21) -> 0.015587971 | S18: 2017 | U18: December
A19: 1 | B19: Select Ending Year for 10-Year Graph. | F19: Whirlpool Rapids Bridge | G19: WPB | I19: =SUMIFS(Traffic!FD:FD,Traffic!$B:$B,Dashboard!$G19,Traffic!$CY:$CY,Dashboard!$F$21) -> 34390 | J19: =SUMIFS(Traffic!FE:FE,Traffic!$B:$B,Dashboard!$G19,Traffic!$CY:$CY,Dashboard!$F$21) -> 39621 | K19: =IF(L19<0,-1,IF(L19=0,0,1)) -> 1 | L19: =SUMIFS(Traffic!FG:FG,Traffic!$B:$B,Dashboard!$G19,Traffic!$CY:$CY,Dashboard!$F$21) -> 0.15210817 | N19: =SUMIFS(Traffic!FI:FI,Traffic!$B:$B,Dashboard!$G19,Traffic!$CY:$CY,Dashboard!$F$21) -> 225108 | O19: =SUMIFS(Traffic!FJ:FJ,Traffic!$B:$B,Dashboard!$G19,Traffic!$CY:$CY,Dashboard!$F$21) -> 246892 | P19: =IF(Q19<0,-1,IF(Q19=0,0,1)) -> 1 | Q19: =SUMIFS(Traffic!FL:FL,Traffic!$B:$B,Dashboard!$G19,Traffic!$CY:$CY,Dashboard!$F$21) -> 0.096771328 | S19: 2018
A20: 2 | B20: Select desired crossing or all crossings for BTOA. | S20: 2019
A21: 3 | B21: Select traffic type or Total BTOA Traffic. | F21: TOTAL | I21: =SUM(I7:I20) -> 2844601 | J21: =SUM(J7:J20) -> 2994524 | K21: =IF(L21<0,-1,IF(L21=0,0,1)) -> 1 | L21: =SUMIFS(Traffic!FG:FG,Traffic!$B:$B,$F21,Traffic!$CY:$CY,Dashboard!$F$21) -> 0.052704404 | N21: =SUM(N7:N20) -> 18654943 | O21: =SUM(O7:O20) -> 19077414 | P21: =IF(Q21<0,-1,IF(Q21=0,0,1)) -> 1 | Q21: =SUMIFS(Traffic!FL:FL,Traffic!$B:$B,$F21,Traffic!$CY:$CY,Dashboard!$F$21) -> 0.022646598 | S21: 2020
A22: 4 | B22: Select Annual or Year-to-Date; view results on "Graph" Tab. | S22: 2021
F23: Passenger Cars | I23: =SUMIFS(Traffic!FD:FD,Traffic!$B:$B,$F21,Traffic!$CY:$CY,$F$23) -> 2307896 | J23: =SUMIFS(Traffic!FE:FE,Traffic!$B:$B,$F21,Traffic!$CY:$CY,$F$23) -> 2426906 | K23: =IF(L23<0,-1,IF(L23=0,0,1)) -> 1 | L23: =SUMIFS(Traffic!FG:FG,Traffic!$B:$B,$F21,Traffic!$CY:$CY,$F$23) -> 0.051566448 | N23: =SUMIFS(Traffic!FI:FI,Traffic!$B:$B,$F21,Traffic!$CY:$CY,$F$23) -> 14312145 | O23: =SUMIFS(Traffic!FJ:FJ,Traffic!$B:$B,$F21,Traffic!$CY:$CY,$F$23) -> 14799779 | P23: =IF(Q23<0,-1,IF(Q23=0,0,1)) -> 1 | Q23: =SUMIFS(Traffic!FL:FL,Traffic!$B:$B,$F21,Traffic!$CY:$CY,$F$23) -> 0.034071343 | S23: 2022
C24: Select Ending Year | D24: 2026 | F24: Trucks | I24: =SUMIFS(Traffic!FD:FD,Traffic!$B:$B,$F21,Traffic!$CY:$CY,$F$24) -> 525638 | J24: =SUMIFS(Traffic!FE:FE,Traffic!$B:$B,$F21,Traffic!$CY:$CY,$F$24) -> 557454 | K24: =IF(L24<0,-1,IF(L24=0,0,1)) -> 1 | L24: =SUMIFS(Traffic!FG:FG,Traffic!$B:$B,$F21,Traffic!$CY:$CY,$F$24) -> 0.060528348 | N24: =SUMIFS(Traffic!FI:FI,Traffic!$B:$B,$F21,Traffic!$CY:$CY,$F$24) -> 4291429 | O24: =SUMIFS(Traffic!FJ:FJ,Traffic!$B:$B,$F21,Traffic!$CY:$CY,$F$24) -> 4230170 | P24: =IF(Q24<0,-1,IF(Q24=0,0,1)) -> -1 | Q24: =SUMIFS(Traffic!FL:FL,Traffic!$B:$B,$F21,Traffic!$CY:$CY,$F$24) -> -0.014274732 | S24: 2023
C25: Select Bridge or Total BTOA Crossings | D25: Total BTOA Traffic | F25: Buses & Misc. | I25: =SUMIFS(Traffic!FD:FD,Traffic!$B:$B,$F21,Traffic!$CY:$CY,$F$25) -> 11067 | J25: =SUMIFS(Traffic!FE:FE,Traffic!$B:$B,$F21,Traffic!$CY:$CY,$F$25) -> 10164 | K25: =IF(L25<0,-1,IF(L25=0,0,1)) -> -1 | L25: =SUMIFS(Traffic!FG:FG,Traffic!$B:$B,$F21,Traffic!$CY:$CY,$F$25) -> -0.081593928 | N25: =SUMIFS(Traffic!FI:FI,Traffic!$B:$B,$F21,Traffic!$CY:$CY,$F$25) -> 51369 | O25: =SUMIFS(Traffic!FJ:FJ,Traffic!$B:$B,$F21,Traffic!$CY:$CY,$F$25) -> 47465 | P25: =IF(Q25<0,-1,IF(Q25=0,0,1)) -> -1 | Q25: =SUMIFS(Traffic!FL:FL,Traffic!$B:$B,$F21,Traffic!$CY:$CY,$F$25) -> -0.075999143 | S25: 2024
C26: Select Traffic Category or Total | D26: Total Crossings | S26: 2025
C27: Annual or Year-to-Date Results | D27: Year-to-Date | F27: TOTAL | I27: =SUM(I23:I26) -> 2844601 | J27: =SUM(J23:J26) -> 2994524 | K27: =IF(L27<0,-1,IF(L27=0,0,1)) -> 1 | L27: =SUMIFS(Traffic!FG:FG,Traffic!$B:$B,$F27,Traffic!$CY:$CY,Dashboard!$F$21) -> 0.052704404 | N27: =SUM(N23:N26) -> 18654943 | O27: =SUM(O23:O26) -> 19077414 | P27: =IF(Q27<0,-1,IF(Q27=0,0,1)) -> 1 | Q27: =SUMIFS(Traffic!FL:FL,Traffic!$B:$B,$F27,Traffic!$CY:$CY,Dashboard!$F$21) -> 0.022646598 | S27: 2026
D29: * No traffic data available prior to 2006.
D31: Gordie Howe Opening Date: July 27, 2026

Sheet Traffic
A1: Bridge and Tunnel Operators Association (BTOA)
A2: Ontario Border Crossings with Michigan & New York
A3: UNITED STATES - CANADA
A4: =CONCATENATE(D8," - ",E8) -> 2025 - 2026 | D4: January | L4: February | T4: March | AB4: April | AJ4: May | AR4: June | AZ4: July | BH4: August | BP4: September | BX4: October | CF4: November | CN4: December
H5: a | I5: b | P5: a | Q5: b | X5: a | Y5: b | AF5: a | AG5: b | AN5: a | AO5: b | AV5: a | AW5: b | BD5: a | BE5: b | BL5: a | BM5: b | BT5: a | BU5: b | CB5: a | CC5: b | CJ5: a | CK5: b | CR5: a | CS5: b
D6: a | E6: b | L6: a | M6: b | T6: a | U6: b | AB6: a | AC6: b | AJ6: a | AK6: b | AR6: a | AS6: b | AZ6: a | BA6: b | BH6: a | BI6: b | BP6: a | BQ6: b | BX6: a | BY6: b | CF6: a | CG6: b | CN6: a | CO6: b | EB6: YEAR TO DATE | EQ6: YEAR TO DATE
D7: January | H7: YEAR-TO-DATE | L7: February | P7: YEAR-TO-DATE | T7: March | X7: YEAR-TO-DATE | AB7: April | AF7: YEAR-TO-DATE | AJ7: May | AN7: YEAR-TO-DATE | AR7: June | AV7: YEAR-TO-DATE | AZ7: July | BD7: YEAR-TO-DATE | BH7: August | BL7: YEAR-TO-DATE | BP7: September | BT7: YEAR-TO-DATE | BX7: October | CB7: YEAR-TO-DATE | CF7: November | CJ7: YEAR-TO-DATE | CN7: December | CR7: YEAR-TO-DATE | DA7: =+$D$8 -> 2025 | DB7: =+DA7 -> 2025 | DC7: =+DB7 -> 2025 | DD7: =+DC7 -> 2025 | DE7: =+DD7 -> 2025 | DF7: =+DE7 -> 2025 | DG7: =+DF7 -> 2025 | DH7: =+DG7 -> 2025 | DI7: =+DH7 -> 2025 | ... DL7: =+DK7 -> 2025 | DO7: =+$E$8 -> 2026 | DP7: =+DO7 -> 2026 | DQ7: =+DP7 -> 2026 | DR7: =+DQ7 -> 2026 | DS7: =+DR7 -> 2026 | DT7: =+DS7 -> 2026 | DU7: =+DT7 -> 2026 | DV7: =+DU7 -> 2026 | DW7: =+DV7 -> 2026 | ... DZ7: =+DY7 -> 2026 | EB7: =+$D$8 -> 2025 | EC7: =+EB7 -> 2025 | ED7: =+EC7 -> 2025 | EE7: =+ED7 -> 2025 | EF7: =+EE7 -> 2025 | EG7: =+EF7 -> 2025 | EH7: =+EG7 -> 2025 | EI7: =+EH7 -> 2025 | EJ7: =+EI7 -> 2025 | ... EM7: =+EL7 -> 2025 | EQ7: =+$E$8 -> 2026 | ER7: =+EQ7 -> 2026 | ES7: =+ER7 -> 2026 | ET7: =+ES7 -> 2026 | EU7: =+ET7 -> 2026 | EV7: =+EU7 -> 2026 | EW7: =+EV7 -> 2026 | EX7: =+EW7 -> 2026 | EY7: =+EX7 -> 2026 | ... FB7: =+FA7 -> 2026 | FD7: =+Dashboard!$C$16 -> August | FE7: =+Dashboard!$C$16 -> August | FI7: =+Dashboard!$C$16 -> August | FJ7: =+Dashboard!$C$16 -> August
A8: Traffic Report for the Month Ending: | D8: =+Dashboard!C13 -> 2025 | E8: =+Dashboard!C14 -> 2026 | F8: Change | G8: Percent | H8: =+$D$8 -> 2025 | I8: =+$E$8 -> 2026 | J8: Change | K8: Percent | L8: =+$D$8 -> 2025 | M8: =+$E$8 -> 2026 | N8: Change | O8: Percent | P8: =+$D$8 -> 2025 | Q8: =+$E$8 -> 2026 | R8: Change | S8: Percent | T8: =+$D$8 -> 2025 | U8: =+$E$8 -> 2026 | V8: Change | W8: Percent | X8: =+$D$8 -> 2025 | Y8: =+$E$8 -> 2026 | Z8: Change | AA8: Percent | AB8: =+$D$8 -> 2025 | AC8: =+$E$8 -> 2026 | AD8: Change | AE8: Percent | AF8: =+$D$8 -> 2025 | AG8: =+$E$8 -> 2026 | AH8: Change | AI8: Percent | AJ8: =+$D$8 -> 2025 | AK8: =+$E$8 -> 2026 | AL8: Change | AM8: Percent | AN8: =+$D$8 -> 2025 | AO8: =+$E$8 -> 2026 | AP8: Change | AQ8: Percent | AR8: =+$D$8 -> 2025 | AS8: =+$E$8 -> 2026 | AT8: Change | AU8: Percent | AV8: =+$D$8 -> 2025 | AW8: =+$E$8 -> 2026 | AX8: Change | AY8: Percent | AZ8: =+$D$8 -> 2025 | BA8: =+$E$8 -> 2026 | BB8: Change | BC8: Percent | BD8: =+$D$8 -> 2025 | BE8: =+$E$8 -> 2026 | BF8: Change | BG8: Percent | BH8: =+$D$8 -> 2025 | BI8: =+$E$8 -> 2026 | BJ8: Change | BK8: Percent | BL8: =+$D$8 -> 2025 | BM8: =+$E$8 -> 2026 | BN8: Change | BO8: Percent | BP8: =+$D$8 -> 2025 | BQ8: =+$E$8 -> 2026 | BR8: Change | BS8: Percent | BT8: =+$D$8 -> 2025 | BU8: =+$E$8 -> 2026 | BV8: Change | BW8: Percent | BX8: =+$D$8 -> 2025 | BY8: =+$E$8 -> 2026 | BZ8: Change | CA8: Percent | CB8: =+$D$8 -> 2025 | CC8: =+$E$8 -> 2026 | CD8: Change | CE8: Percent | CF8: =+$D$8 -> 2025 | CG8: =+$E$8 -> 2026 | CH8: Change | CI8: Percent | CJ8: =+$D$8 -> 2025 | CK8: =+$E$8 -> 2026 | CL8: Change | CM8: Percent | CN8: =+$D$8 -> 2025 | CO8: =+$E$8 -> 2026 | CP8: Change | CQ8: Percent | CR8: =+$D$8 -> 2025 | CS8: =+$E$8 -> 2026 | CT8: Change | CU8: Percent | DA8: JANUARY | DB8: FEBRUARY | DC8: MARCH | DD8: APRIL | DE8: MAY | DF8: JUNE | DG8: JULY | DH8: AUGUST | DI8: SEPTEMBER | DJ8: OCTOBER | DK8: NOVEMBER | DL8: DECEMBER | DO8: JANUARY | DP8: FEBRUARY | DQ8: MARCH | DR8: APRIL | DS8: MAY | DT8: JUNE | DU8: JULY | DV8: AUGUST | DW8: SEPTEMBER | DX8: OCTOBER | DY8: NOVEMBER | DZ8: DECEMBER | EB8: JANUARY | EC8: FEBRUARY | ED8: MARCH | EE8: APRIL | EF8: MAY | EG8: JUNE | EH8: JULY | EI8: AUGUST | EJ8: SEPTEMBER | EK8: OCTOBER | EL8: NOVEMBER | EM8: DECEMBER | EQ8: JANUARY | ER8: FEBRUARY | ES8: MARCH | ET8: APRIL | EU8: MAY | EV8: JUNE | EW8: JULY | EX8: AUGUST | EY8: SEPTEMBER | EZ8: OCTOBER | FA8: NOVEMBER | FB8: DECEMBER | FD8: =+Dashboard!$C$13 -> 2025 | FE8: =+Dashboard!$C$14 -> 2026 | FF8: Change | FG8: Percent | FI8: =+Dashboard!$C$13 -> 2025 | FJ8: =+Dashboard!$C$14 -> 2026 | FK8: Change | FL8: Percent
B9: AAZ | C9: Passenger Cars | D9: =+DA9 -> 14814 | E9: =OFFSET(DA9,0,14,1,1) -> 12792 | F9: =SUM(E9-D9) -> -2022 | G9: =IF(F9=0,0,IF(D9=0,1,F9/D9)) -> -0.13649251 | H9: =SUMIF($D$6:G$6,H$5,$D9:G9) -> 14814 | I9: =SUMIF($D$6:H$6,I$5,$D9:H9) -> 12792 | J9: =SUM(I9-H9) -> -2022 | K9: =IF(J9=0,0,IF(H9=0,1,J9/H9)) -> -0.13649251 | L9: =+DB9 -> 12302 | M9: =OFFSET(DB9,0,14,1,1) -> 10742 | N9: =SUM(M9-L9) -> -1560 | O9: =IF(N9=0,0,IF(L9=0,1,N9/L9)) -> -0.12680865 | P9: =SUMIF($D$6:O$6,P$5,$D9:O9) -> 27116 | Q9: =SUMIF($D$6:P$6,Q$5,$D9:P9) -> 23534 | R9: =SUM(Q9-P9) -> -3582 | S9: =IF(R9=0,0,IF(P9=0,1,R9/P9)) -> -0.13209913 | T9: =+DC9 -> 11263 | U9: =OFFSET(DC9,0,14,1,1) -> 12388 | V9: =SUM(U9-T9) -> 1125 | W9: =IF(V9=0,0,IF(T9=0,1,V9/T9)) -> 0.099884578 | X9: =SUMIF($D$6:W$6,X$5,$D9:W9) -> 38379 | Y9: =SUMIF($D$6:X$6,Y$5,$D9:X9) -> 35922 | Z9: =SUM(Y9-X9) -> -2457 | AA9: =IF(Z9=0,0,IF(X9=0,1,Z9/X9)) -> -0.064019386 | AB9: =+DD9 -> 10359 | AC9: =OFFSET(DD9,0,14,1,1) -> 12652 | AD9: =SUM(AC9-AB9) -> 2293 | AE9: =IF(AD9=0,0,IF(AB9=0,1,AD9/AB9)) -> 0.22135341 | AF9: =SUMIF($D$6:AE$6,AF$5,$D9:AE9) -> 48738 | AG9: =SUMIF($D$6:AF$6,AG$5,$D9:AF9) -> 48574 | AH9: =SUM(AG9-AF9) -> -164 | AI9: =IF(AH9=0,0,IF(AF9=0,1,AH9/AF9)) -> -0.0033649309 | AJ9: =+DE9 -> 19433 | AK9: =OFFSET(DE9,0,14,1,1) -> 22545 | AL9: =SUM(AK9-AJ9) -> 3112 | AM9: =IF(AL9=0,0,IF(AJ9=0,1,AL9/AJ9)) -> 0.16013997 | AN9: =SUMIF($D$6:AM$6,AN$5,$D9:AM9) -> 68171 | AO9: =SUMIF($D$6:AN$6,AO$5,$D9:AN9) -> 71119 | AP9: =SUM(AO9-AN9) -> 2948 | AQ9: =IF(AP9=0,0,IF(AN9=0,1,AP9/AN9)) -> 0.043244195 | AR9: =+DF9 -> 29651 | AS9: =OFFSET(DF9,0,14,1,1) -> 29011 | AT9: =SUM(AS9-AR9) -> -640 | AU9: =IF(AT9=0,0,IF(AR9=0,1,AT9/AR9)) -> -0.021584432 | AV9: =SUMIF($D$6:AU$6,AV$5,$D9:AU9) -> 97822 | AW9: =SUMIF($D$6:AV$6,AW$5,$D9:AV9) -> 100130 | AX9: =SUM(AW9-AV9) -> 2308 | AY9: =IF(AX9=0,0,IF(AV9=0,1,AX9/AV9)) -> 0.023593875 | AZ9: =+DG9 -> 25974 | BA9: =OFFSET(DG9,0,14,1,1) -> 27758 | BB9: =SUM(BA9-AZ9) -> 1784 | BC9: =IF(BB9=0,0,IF(AZ9=0,1,BB9/AZ9)) -> 0.068684069 | BD9: =SUMIF($D$6:BC$6,BD$5,$D9:BC9) -> 123796 | BE9: =SUMIF($D$6:BD$6,BE$5,$D9:BD9) -> 127888 | BF9: =SUM(BE9-BD9) -> 4092 | BG9: =IF(BF9=0,0,IF(BD9=0,1,BF9/BD9)) -> 0.03305438 | BH9: =+DH9 -> 25398 | BI9: =OFFSET(DH9,0,14,1,1) -> 25827 | BJ9: =SUM(BI9-BH9) -> 429 | BK9: =IF(BJ9=0,0,IF(BH9=0,1,BJ9/BH9)) -> 0.016891094 | BL9: =SUMIF($D$6:BK$6,BL$5,$D9:BK9) -> 149194 | BM9: =SUMIF($D$6:BL$6,BM$5,$D9:BL9) -> 153715 | BN9: =SUM(BM9-BL9) -> 4521 | BO9: =IF(BN9=0,0,IF(BL9=0,1,BN9/BL9)) -> 0.030302827 | BP9: =+DI9 -> 19080 | BQ9: =OFFSET(DI9,0,14,1,1) -> 0 | BR9: =SUM(BQ9-BP9) -> -19080 | BS9: =IF(BR9=0,0,IF(BP9=0,1,BR9/BP9)) -> -1 | BT9: =SUMIF($D$6:BS$6,BT$5,$D9:BS9) -> 168274 | BU9: =SUMIF($D$6:BT$6,BU$5,$D9:BT9) -> 153715 | BV9: =SUM(BU9-BT9) -> -14559 | BW9: =IF(BV9=0,0,IF(BT9=0,1,BV9/BT9)) -> -0.086519605 | BX9: =+DJ9 -> 14295 | BY9: =OFFSET(DJ9,0,14,1,1) -> 0 | BZ9: =SUM(BY9-BX9) -> -14295 | CA9: =IF(BZ9=0,0,IF(BX9=0,1,BZ9/BX9)) -> -1 | CB9: =SUMIF($D$6:CA$6,CB$5,$D9:CA9) -> 182569 | CC9: =SUMIF($D$6:CB$6,CC$5,$D9:CB9) -> 153715 | CD9: =SUM(CC9-CB9) -> -28854 | CE9: =IF(CD9=0,0,IF(CB9=0,1,CD9/CB9)) -> -0.15804436 | CF9: =+DK9 -> 12504 | CG9: =OFFSET(DK9,0,14,1,1) -> 0 | CH9: =SUM(CG9-CF9) -> -12504 | CI9: =IF(CH9=0,0,IF(CF9=0,1,CH9/CF9)) -> -1 | CJ9: =SUMIF($D$6:CI$6,CJ$5,$D9:CI9) -> 195073 | CK9: =SUMIF($D$6:CJ$6,CK$5,$D9:CJ9) -> 153715 | CL9: =SUM(CK9-CJ9) -> -41358 | CM9: =IF(CL9=0,0,IF(CJ9=0,1,CL9/CJ9)) -> -0.21201294 | CN9: =+DL9 -> 13751 | CO9: =OFFSET(DL9,0,14,1,1) -> 0 | CP9: =SUM(CO9-CN9) -> -13751 | CQ9: =IF(CP9=0,0,IF(CN9=0,1,CP9/CN9)) -> -1 | CR9: =SUMIF($D$6:CQ$6,CR$5,$D9:CQ9) -> 208824 | CS9: =SUMIF($D$6:CR$6,CS$5,$D9:CR9) -> 153715 | CT9: =SUM(CS9-CR9) -> -55109 | CU9: =IF(CT9=0,0,IF(CR9=0,1,CT9/CR9)) -> -0.26390166 | CX9: Aazhogan Bridge | CY9: Passenger Cars | DA9: =SUMIF(AAZ!$A$131:$A$138,Traffic!DA$7,AAZ!E$131:E$138) -> 14814 | DB9: =SUMIF(AAZ!$A$131:$A$138,Traffic!DB$7,AAZ!F$131:F$138) -> 12302 | DC9: =SUMIF(AAZ!$A$131:$A$138,Traffic!DC$7,AAZ!G$131:G$138) -> 11263 | DD9: =SUMIF(AAZ!$A$131:$A$138,Traffic!DD$7,AAZ!H$131:H$138) -> 10359 | DE9: =SUMIF(AAZ!$A$131:$A$138,Traffic!DE$7,AAZ!I$131:I$138) -> 19433 | DF9: =SUMIF(AAZ!$A$131:$A$138,Traffic!DF$7,AAZ!J$131:J$138) -> 29651 | DG9: =SUMIF(AAZ!$A$131:$A$138,Traffic!DG$7,AAZ!K$131:K$138) -> 25974 | DH9: =SUMIF(AAZ!$A$131:$A$138,Traffic!DH$7,AAZ!L$131:L$138) -> 25398 | ... DL9: =SUMIF(AAZ!$A$131:$A$138,Traffic!DL$7,AAZ!P$131:P$138) -> 13751 | DO9: =SUMIF(AAZ!$A$131:$A$138,Traffic!DO$7,AAZ!E$131:E$138) -> 12792 | DP9: =SUMIF(AAZ!$A$131:$A$138,Traffic!DP$7,AAZ!F$131:F$138) -> 10742 | DQ9: =SUMIF(AAZ!$A$131:$A$138,Traffic!DQ$7,AAZ!G$131:G$138) -> 12388 | DR9: =SUMIF(AAZ!$A$131:$A$138,Traffic!DR$7,AAZ!H$131:H$138) -> 12652 | DS9: =SUMIF(AAZ!$A$131:$A$138,Traffic!DS$7,AAZ!I$131:I$138) -> 22545 | DT9: =SUMIF(AAZ!$A$131:$A$138,Traffic!DT$7,AAZ!J$131:J$138) -> 29011 | DU9: =SUMIF(AAZ!$A$131:$A$138,Traffic!DU$7,AAZ!K$131:K$138) -> 27758 | DV9: =SUMIF(AAZ!$A$131:$A$138,Traffic!DV$7,AAZ!L$131:L$138) -> 25827 | ... DZ9: =SUMIF(AAZ!$A$131:$A$138,Traffic!DZ$7,AAZ!P$131:P$138) -> 0 | EB9: =SUM(DA9) -> 14814 | EC9: =SUM($DA9:DB9) -> 27116 | ED9: =SUM($DA9:DC9) -> 38379 | EE9: =SUM($DA9:DD9) -> 48738 | EF9: =SUM($DA9:DE9) -> 68171 | EG9: =SUM($DA9:DF9) -> 97822 | EH9: =SUM($DA9:DG9) -> 123796 | EI9: =SUM($DA9:DH9) -> 149194 | EJ9: =SUM($DA9:DI9) -> 168274 | ... EM9: =SUM($DA9:DL9) -> 208824 | EQ9: =SUM($DO9:DO9) -> 12792 | ER9: =SUM($DO9:DP9) -> 23534 | ES9: =SUM($DO9:DQ9) -> 35922 | ET9: =SUM($DO9:DR9) -> 48574 | EU9: =SUM($DO9:DS9) -> 71119 | EV9: =SUM($DO9:DT9) -> 100130 | EW9: =SUM($DO9:DU9) -> 127888 | EX9: =SUM($DO9:DV9) -> 153715 | ... FB9: =SUM($DO9:DZ9) -> 153715 | FD9: =SUMIFS($DA9:$DZ9,$DA$8:$DZ$8,FD$7,$DA$7:$DZ$7,FD$8) -> 25398 | FE9: =SUMIFS($DA9:$DZ9,$DA$8:$DZ$8,FE$7,$DA$7:$DZ$7,FE$8) -> 25827 | FF9: =+FE9-FD9 -> 429 | FG9: =IFERROR(FF9/FD9,1) -> 0.016891094 | FI9: =SUMIFS($EB9:$FB9,$EB$8:$FB$8,FI$7,$EB$7:$FB$7,FI$8) -> 149194 | FJ9: =SUMIFS($EB9:$FB9,$EB$8:$FB$8,FJ$7,$EB$7:$FB$7,FJ$8) -> 153715 | FK9: =+FJ9-FI9 -> 4521 | FL9: =IFERROR(FK9/FI9,1) -> 0.030302827
A10: =+CX11 -> Aazhogan Bridge | B10: AAZ | C10: Trucks | D10: =+DA10 -> 931 | E10: =OFFSET(DA10,0,14,1,1) -> 544 | F10: =SUM(E10-D10) -> -387 | G10: =IF(F10=0,0,IF(D10=0,1,F10/D10)) -> -0.41568206 | H10: =SUMIF($D$6:G$6,H$5,$D10:G10) -> 931 | I10: =SUMIF($D$6:H$6,I$5,$D10:H10) -> 544 | J10: =SUM(I10-H10) -> -387 | K10: =IF(J10=0,0,IF(H10=0,1,J10/H10)) -> -0.41568206 | L10: =+DB10 -> 884 | M10: =OFFSET(DB10,0,14,1,1) -> 594 | N10: =SUM(M10-L10) -> -290 | O10: =IF(N10=0,0,IF(L10=0,1,N10/L10)) -> -0.3280543 | P10: =SUMIF($D$6:O$6,P$5,$D10:O10) -> 1815 | Q10: =SUMIF($D$6:P$6,Q$5,$D10:P10) -> 1138 | R10: =SUM(Q10-P10) -> -677 | S10: =IF(R10=0,0,IF(P10=0,1,R10/P10)) -> -0.37300275 | T10: =+DC10 -> 739 | U10: =OFFSET(DC10,0,14,1,1) -> 751 | V10: =SUM(U10-T10) -> 12 | W10: =IF(V10=0,0,IF(T10=0,1,V10/T10)) -> 0.01623816 | X10: =SUMIF($D$6:W$6,X$5,$D10:W10) -> 2554 | Y10: =SUMIF($D$6:X$6,Y$5,$D10:X10) -> 1889 | Z10: =SUM(Y10-X10) -> -665 | AA10: =IF(Z10=0,0,IF(X10=0,1,Z10/X10)) -> -0.26037588 | AB10: =+DD10 -> 568 | AC10: =OFFSET(DD10,0,14,1,1) -> 510 | AD10: =SUM(AC10-AB10) -> -58 | AE10: =IF(AD10=0,0,IF(AB10=0,1,AD10/AB10)) -> -0.10211268 | AF10: =SUMIF($D$6:AE$6,AF$5,$D10:AE10) -> 3122 | AG10: =SUMIF($D$6:AF$6,AG$5,$D10:AF10) -> 2399 | AH10: =SUM(AG10-AF10) -> -723 | AI10: =IF(AH10=0,0,IF(AF10=0,1,AH10/AF10)) -> -0.23158232 | AJ10: =+DE10 -> 567 | AK10: =OFFSET(DE10,0,14,1,1) -> 564 | AL10: =SUM(AK10-AJ10) -> -3 | AM10: =IF(AL10=0,0,IF(AJ10=0,1,AL10/AJ10)) -> -0.0052910053 | AN10: =SUMIF($D$6:AM$6,AN$5,$D10:AM10) -> 3689 | AO10: =SUMIF($D$6:AN$6,AO$5,$D10:AN10) -> 2963 | AP10: =SUM(AO10-AN10) -> -726 | AQ10: =IF(AP10=0,0,IF(AN10=0,1,AP10/AN10)) -> -0.1968013 | AR10: =+DF10 -> 568 | AS10: =OFFSET(DF10,0,14,1,1) -> 620 | AT10: =SUM(AS10-AR10) -> 52 | AU10: =IF(AT10=0,0,IF(AR10=0,1,AT10/AR10)) -> 0.091549296 | AV10: =SUMIF($D$6:AU$6,AV$5,$D10:AU10) -> 4257 | AW10: =SUMIF($D$6:AV$6,AW$5,$D10:AV10) -> 3583 | AX10: =SUM(AW10-AV10) -> -674 | AY10: =IF(AX10=0,0,IF(AV10=0,1,AX10/AV10)) -> -0.15832746 | AZ10: =+DG10 -> 693 | BA10: =OFFSET(DG10,0,14,1,1) -> 556 | BB10: =SUM(BA10-AZ10) -> -137 | BC10: =IF(BB10=0,0,IF(AZ10=0,1,BB10/AZ10)) -> -0.1976912 | BD10: =SUMIF($D$6:BC$6,BD$5,$D10:BC10) -> 4950 | BE10: =SUMIF($D$6:BD$6,BE$5,$D10:BD10) -> 4139 | BF10: =SUM(BE10-BD10) -> -811 | BG10: =IF(BF10=0,0,IF(BD10=0,1,BF10/BD10)) -> -0.16383838 | BH10: =+DH10 -> 633 | BI10: =OFFSET(DH10,0,14,1,1) -> 549 | BJ10: =SUM(BI10-BH10) -> -84 | BK10: =IF(BJ10=0,0,IF(BH10=0,1,BJ10/BH10)) -> -0.13270142 | BL10: =SUMIF($D$6:BK$6,BL$5,$D10:BK10) -> 5583 | BM10: =SUMIF($D$6:BL$6,BM$5,$D10:BL10) -> 4688 | BN10: =SUM(BM10-BL10) -> -895 | BO10: =IF(BN10=0,0,IF(BL10=0,1,BN10/BL10)) -> -0.16030808 | BP10: =+DI10 -> 733 | BQ10: =OFFSET(DI10,0,14,1,1) -> 0 | BR10: =SUM(BQ10-BP10) -> -733 | BS10: =IF(BR10=0,0,IF(BP10=0,1,BR10/BP10)) -> -1 | BT10: =SUMIF($D$6:BS$6,BT$5,$D10:BS10) -> 6316 | BU10: =SUMIF($D$6:BT$6,BU$5,$D10:BT10) -> 4688 | BV10: =SUM(BU10-BT10) -> -1628 | BW10: =IF(BV10=0,0,IF(BT10=0,1,BV10/BT10)) -> -0.25775807 | BX10: =+DJ10 -> 674 | BY10: =OFFSET(DJ10,0,14,1,1) -> 0 | BZ10: =SUM(BY10-BX10) -> -674 | CA10: =IF(BZ10=0,0,IF(BX10=0,1,BZ10/BX10)) -> -1 | CB10: =SUMIF($D$6:CA$6,CB$5,$D10:CA10) -> 6990 | CC10: =SUMIF($D$6:CB$6,CC$5,$D10:CB10) -> 4688 | CD10: =SUM(CC10-CB10) -> -2302 | CE10: =IF(CD10=0,0,IF(CB10=0,1,CD10/CB10)) -> -0.32932761 | CF10: =+DK10 -> 634 | CG10: =OFFSET(DK10,0,14,1,1) -> 0 | CH10: =SUM(CG10-CF10) -> -634 | CI10: =IF(CH10=0,0,IF(CF10=0,1,CH10/CF10)) -> -1 | CJ10: =SUMIF($D$6:CI$6,CJ$5,$D10:CI10) -> 7624 | CK10: =SUMIF($D$6:CJ$6,CK$5,$D10:CJ10) -> 4688 | CL10: =SUM(CK10-CJ10) -> -2936 | CM10: =IF(CL10=0,0,IF(CJ10=0,1,CL10/CJ10)) -> -0.38509969 | CN10: =+DL10 -> 582 | CO10: =OFFSET(DL10,0,14,1,1) -> 0 | CP10: =SUM(CO10-CN10) -> -582 | CQ10: =IF(CP10=0,0,IF(CN10=0,1,CP10/CN10)) -> -1 | CR10: =SUMIF($D$6:CQ$6,CR$5,$D10:CQ10) -> 8206 | CS10: =SUMIF($D$6:CR$6,CS$5,$D10:CR10) -> 4688 | CT10: =SUM(CS10-CR10) -> -3518 | CU10: =IF(CT10=0,0,IF(CR10=0,1,CT10/CR10)) -> -0.4287107 | CX10: Aazhogan Bridge | CY10: Trucks | DA10: =SUMIF(AAZ!$A$154:$A$161,Traffic!DA$7,AAZ!E$154:E$161) -> 931 | DB10: =SUMIF(AAZ!$A$154:$A$161,Traffic!DB$7,AAZ!F$154:F$161) -> 884 | DC10: =SUMIF(AAZ!$A$154:$A$161,Traffic!DC$7,AAZ!G$154:G$161) -> 739 | DD10: =SUMIF(AAZ!$A$154:$A$161,Traffic!DD$7,AAZ!H$154:H$161) -> 568 | DE10: =SUMIF(AAZ!$A$154:$A$161,Traffic!DE$7,AAZ!I$154:I$161) -> 567 | DF10: =SUMIF(AAZ!$A$154:$A$161,Traffic!DF$7,AAZ!J$154:J$161) -> 568 | DG10: =SUMIF(AAZ!$A$154:$A$161,Traffic!DG$7,AAZ!K$154:K$161) -> 693 | DH10: =SUMIF(AAZ!$A$154:$A$161,Traffic!DH$7,AAZ!L$154:L$161) -> 633 | ... DL10: =SUMIF(AAZ!$A$154:$A$161,Traffic!DL$7,AAZ!P$154:P$161) -> 582 | DO10: =SUMIF(AAZ!$A$154:$A$161,Traffic!DO$7,AAZ!E$154:E$161) -> 544 | DP10: =SUMIF(AAZ!$A$154:$A$161,Traffic!DP$7,AAZ!F$154:F$161) -> 594 | DQ10: =SUMIF(AAZ!$A$154:$A$161,Traffic!DQ$7,AAZ!G$154:G$161) -> 751 | DR10: =SUMIF(AAZ!$A$154:$A$161,Traffic!DR$7,AAZ!H$154:H$161) -> 510 | DS10: =SUMIF(AAZ!$A$154:$A$161,Traffic!DS$7,AAZ!I$154:I$161) -> 564 | DT10: =SUMIF(AAZ!$A$154:$A$161,Traffic!DT$7,AAZ!J$154:J$161) -> 620 | DU10: =SUMIF(AAZ!$A$154:$A$161,Traffic!DU$7,AAZ!K$154:K$161) -> 556 | DV10: =SUMIF(AAZ!$A$154:$A$161,Traffic!DV$7,AAZ!L$154:L$161) -> 549 | ... DZ10: =SUMIF(AAZ!$A$154:$A$161,Traffic!DZ$7,AAZ!P$154:P$161) -> 0 | EB10: =SUM(DA10) -> 931 | EC10: =SUM($DA10:DB10) -> 1815 | ED10: =SUM($DA10:DC10) -> 2554 | EE10: =SUM($DA10:DD10) -> 3122 | EF10: =SUM($DA10:DE10) -> 3689 | EG10: =SUM($DA10:DF10) -> 4257 | EH10: =SUM($DA10:DG10) -> 4950 | EI10: =SUM($DA10:DH10) -> 5583 | EJ10: =SUM($DA10:DI10) -> 6316 | ... EM10: =SUM($DA10:DL10) -> 8206 | EQ10: =SUM($DO10:DO10) -> 544 | ER10: =SUM($DO10:DP10) -> 1138 | ES10: =SUM($DO10:DQ10) -> 1889 | ET10: =SUM($DO10:DR10) -> 2399 | EU10: =SUM($DO10:DS10) -> 2963 | EV10: =SUM($DO10:DT10) -> 3583 | EW10: =SUM($DO10:DU10) -> 4139 | EX10: =SUM($DO10:DV10) -> 4688 | ... FB10: =SUM($DO10:DZ10) -> 4688 | FD10: =SUMIFS($DA10:$DZ10,$DA$8:$DZ$8,FD$7,$DA$7:$DZ$7,FD$8) -> 633 | FE10: =SUMIFS($DA10:$DZ10,$DA$8:$DZ$8,FE$7,$DA$7:$DZ$7,FE$8) -> 549 | FF10: =+FE10-FD10 -> -84 | FG10: =IFERROR(FF10/FD10,1) -> -0.13270142 | FI10: =SUMIFS($EB10:$FB10,$EB$8:$FB$8,FI$7,$EB$7:$FB$7,FI$8) -> 5583 | FJ10: =SUMIFS($EB10:$FB10,$EB$8:$FB$8,FJ$7,$EB$7:$FB$7,FJ$8) -> 4688 | FK10: =+FJ10-FI10 -> -895 | FL10: =IFERROR(FK10/FI10,1) -> -0.16030808
A11: (Northbound Traffic Volumes Only) | B11: AAZ | C11: Buses & Misc. | D11: =+DA11 -> 18 | E11: =OFFSET(DA11,0,14,1,1) -> 7 | F11: =SUM(E11-D11) -> -11 | G11: =IF(F11=0,0,IF(D11=0,1,F11/D11)) -> -0.61111111 | H11: =SUMIF($D$6:G$6,H$5,$D11:G11) -> 18 | I11: =SUMIF($D$6:H$6,I$5,$D11:H11) -> 7 | J11: =SUM(I11-H11) -> -11 | K11: =IF(J11=0,0,IF(H11=0,1,J11/H11)) -> -0.61111111 | L11: =+DB11 -> 10 | M11: =OFFSET(DB11,0,14,1,1) -> 6 | N11: =SUM(M11-L11) -> -4 | O11: =IF(N11=0,0,IF(L11=0,1,N11/L11)) -> -0.4 | P11: =SUMIF($D$6:O$6,P$5,$D11:O11) -> 28 | Q11: =SUMIF($D$6:P$6,Q$5,$D11:P11) -> 13 | R11: =SUM(Q11-P11) -> -15 | S11: =IF(R11=0,0,IF(P11=0,1,R11/P11)) -> -0.53571429 | T11: =+DC11 -> 14 | U11: =OFFSET(DC11,0,14,1,1) -> 10 | V11: =SUM(U11-T11) -> -4 | W11: =IF(V11=0,0,IF(T11=0,1,V11/T11)) -> -0.28571429 | X11: =SUMIF($D$6:W$6,X$5,$D11:W11) -> 42 | Y11: =SUMIF($D$6:X$6,Y$5,$D11:X11) -> 23 | Z11: =SUM(Y11-X11) -> -19 | AA11: =IF(Z11=0,0,IF(X11=0,1,Z11/X11)) -> -0.45238095 | AB11: =+DD11 -> 10 | AC11: =OFFSET(DD11,0,14,1,1) -> 15 | AD11: =SUM(AC11-AB11) -> 5 | AE11: =IF(AD11=0,0,IF(AB11=0,1,AD11/AB11)) -> 0.5 | AF11: =SUMIF($D$6:AE$6,AF$5,$D11:AE11) -> 52 | AG11: =SUMIF($D$6:AF$6,AG$5,$D11:AF11) -> 38 | AH11: =SUM(AG11-AF11) -> -14 | AI11: =IF(AH11=0,0,IF(AF11=0,1,AH11/AF11)) -> -0.26923077 | AJ11: =+DE11 -> 107 | AK11: =OFFSET(DE11,0,14,1,1) -> 112 | AL11: =SUM(AK11-AJ11) -> 5 | AM11: =IF(AL11=0,0,IF(AJ11=0,1,AL11/AJ11)) -> 0.046728972 | AN11: =SUMIF($D$6:AM$6,AN$5,$D11:AM11) -> 159 | AO11: =SUMIF($D$6:AN$6,AO$5,$D11:AN11) -> 150 | AP11: =SUM(AO11-AN11) -> -9 | AQ11: =IF(AP11=0,0,IF(AN11=0,1,AP11/AN11)) -> -0.056603774 | AR11: =+DF11 -> 95 | AS11: =OFFSET(DF11,0,14,1,1) -> 208 | AT11: =SUM(AS11-AR11) -> 113 | AU11: =IF(AT11=0,0,IF(AR11=0,1,AT11/AR11)) -> 1.1894737 | AV11: =SUMIF($D$6:AU$6,AV$5,$D11:AU11) -> 254 | AW11: =SUMIF($D$6:AV$6,AW$5,$D11:AV11) -> 358 | AX11: =SUM(AW11-AV11) -> 104 | AY11: =IF(AX11=0,0,IF(AV11=0,1,AX11/AV11)) -> 0.40944882 | AZ11: =+DG11 -> 271 | BA11: =OFFSET(DG11,0,14,1,1) -> 265 | BB11: =SUM(BA11-AZ11) -> -6 | BC11: =IF(BB11=0,0,IF(AZ11=0,1,BB11/AZ11)) -> -0.022140221 | BD11: =SUMIF($D$6:BC$6,BD$5,$D11:BC11) -> 525 | BE11: =SUMIF($D$6:BD$6,BE$5,$D11:BD11) -> 623 | BF11: =SUM(BE11-BD11) -> 98 | BG11: =IF(BF11=0,0,IF(BD11=0,1,BF11/BD11)) -> 0.18666667 | BH11: =+DH11 -> 232 | BI11: =OFFSET(DH11,0,14,1,1) -> 226 | BJ11: =SUM(BI11-BH11) -> -6 | BK11: =IF(BJ11=0,0,IF(BH11=0,1,BJ11/BH11)) -> -0.025862069 | BL11: =SUMIF($D$6:BK$6,BL$5,$D11:BK11) -> 757 | BM11: =SUMIF($D$6:BL$6,BM$5,$D11:BL11) -> 849 | BN11: =SUM(BM11-BL11) -> 92 | BO11: =IF(BN11=0,0,IF(BL11=0,1,BN11/BL11)) -> 0.12153236 | BP11: =+DI11 -> 131 | BQ11: =OFFSET(DI11,0,14,1,1) -> 0 | BR11: =SUM(BQ11-BP11) -> -131 | BS11: =IF(BR11=0,0,IF(BP11=0,1,BR11/BP11)) -> -1 | BT11: =SUMIF($D$6:BS$6,BT$5,$D11:BS11) -> 888 | BU11: =SUMIF($D$6:BT$6,BU$5,$D11:BT11) -> 849 | BV11: =SUM(BU11-BT11) -> -39 | BW11: =IF(BV11=0,0,IF(BT11=0,1,BV11/BT11)) -> -0.043918919 | BX11: =+DJ11 -> 38 | BY11: =OFFSET(DJ11,0,14,1,1) -> 0 | BZ11: =SUM(BY11-BX11) -> -38 | CA11: =IF(BZ11=0,0,IF(BX11=0,1,BZ11/BX11)) -> -1 | CB11: =SUMIF($D$6:CA$6,CB$5,$D11:CA11) -> 926 | CC11: =SUMIF($D$6:CB$6,CC$5,$D11:CB11) -> 849 | CD11: =SUM(CC11-CB11) -> -77 | CE11: =IF(CD11=0,0,IF(CB11=0,1,CD11/CB11)) -> -0.083153348 | CF11: =+DK11 -> 7 | CG11: =OFFSET(DK11,0,14,1,1) -> 0 | CH11: =SUM(CG11-CF11) -> -7 | CI11: =IF(CH11=0,0,IF(CF11=0,1,CH11/CF11)) -> -1 | CJ11: =SUMIF($D$6:CI$6,CJ$5,$D11:CI11) -> 933 | CK11: =SUMIF($D$6:CJ$6,CK$5,$D11:CJ11) -> 849 | CL11: =SUM(CK11-CJ11) -> -84 | CM11: =IF(CL11=0,0,IF(CJ11=0,1,CL11/CJ11)) -> -0.090032154 | CN11: =+DL11 -> 9 | CO11: =OFFSET(DL11,0,14,1,1) -> 0 | CP11: =SUM(CO11-CN11) -> -9 | CQ11: =IF(CP11=0,0,IF(CN11=0,1,CP11/CN11)) -> -1 | CR11: =SUMIF($D$6:CQ$6,CR$5,$D11:CQ11) -> 942 | CS11: =SUMIF($D$6:CR$6,CS$5,$D11:CR11) -> 849 | CT11: =SUM(CS11-CR11) -> -93 | CU11: =IF(CT11=0,0,IF(CR11=0,1,CT11/CR11)) -> -0.098726115 | CX11: Aazhogan Bridge | CY11: Buses & Misc. | DA11: =SUMIF(AAZ!$A$177:$A$184,Traffic!DA$7,AAZ!E$177:E$184) -> 18 | DB11: =SUMIF(AAZ!$A$177:$A$184,Traffic!DB$7,AAZ!F$177:F$184) -> 10 | DC11: =SUMIF(AAZ!$A$177:$A$184,Traffic!DC$7,AAZ!G$177:G$184) -> 14 | DD11: =SUMIF(AAZ!$A$177:$A$184,Traffic!DD$7,AAZ!H$177:H$184) -> 10 | DE11: =SUMIF(AAZ!$A$177:$A$184,Traffic!DE$7,AAZ!I$177:I$184) -> 107 | DF11: =SUMIF(AAZ!$A$177:$A$184,Traffic!DF$7,AAZ!J$177:J$184) -> 95 | DG11: =SUMIF(AAZ!$A$177:$A$184,Traffic!DG$7,AAZ!K$177:K$184) -> 271 | DH11: =SUMIF(AAZ!$A$177:$A$184,Traffic!DH$7,AAZ!L$177:L$184) -> 232 | ... DL11: =SUMIF(AAZ!$A$177:$A$184,Traffic!DL$7,AAZ!P$177:P$184) -> 9 | DO11: =SUMIF(AAZ!$A$177:$A$184,Traffic!DO$7,AAZ!E$177:E$184) -> 7 | DP11: =SUMIF(AAZ!$A$177:$A$184,Traffic!DP$7,AAZ!F$177:F$184) -> 6 | DQ11: =SUMIF(AAZ!$A$177:$A$184,Traffic!DQ$7,AAZ!G$177:G$184) -> 10 | DR11: =SUMIF(AAZ!$A$177:$A$184,Traffic!DR$7,AAZ!H$177:H$184) -> 15 | DS11: =SUMIF(AAZ!$A$177:$A$184,Traffic!DS$7,AAZ!I$177:I$184) -> 112 | DT11: =SUMIF(AAZ!$A$177:$A$184,Traffic!DT$7,AAZ!J$177:J$184) -> 208 | DU11: =SUMIF(AAZ!$A$177:$A$184,Traffic!DU$7,AAZ!K$177:K$184) -> 265 | DV11: =SUMIF(AAZ!$A$177:$A$184,Traffic!DV$7,AAZ!L$177:L$184) -> 226 | ... DZ11: =SUMIF(AAZ!$A$177:$A$184,Traffic!DZ$7,AAZ!P$177:P$184) -> 0 | EB11: =SUM(DA11) -> 18 | EC11: =SUM($DA11:DB11) -> 28 | ED11: =SUM($DA11:DC11) -> 42 | EE11: =SUM($DA11:DD11) -> 52 | EF11: =SUM($DA11:DE11) -> 159 | EG11: =SUM($DA11:DF11) -> 254 | EH11: =SUM($DA11:DG11) -> 525 | EI11: =SUM($DA11:DH11) -> 757 | EJ11: =SUM($DA11:DI11) -> 888 | ... EM11: =SUM($DA11:DL11) -> 942 | EQ11: =SUM($DO11:DO11) -> 7 | ER11: =SUM($DO11:DP11) -> 13 | ES11: =SUM($DO11:DQ11) -> 23 | ET11: =SUM($DO11:DR11) -> 38 | EU11: =SUM($DO11:DS11) -> 150 | EV11: =SUM($DO11:DT11) -> 358 | EW11: =SUM($DO11:DU11) -> 623 | EX11: =SUM($DO11:DV11) -> 849 | ... FB11: =SUM($DO11:DZ11) -> 849 | FD11: =SUMIFS($DA11:$DZ11,$DA$8:$DZ$8,FD$7,$DA$7:$DZ$7,FD$8) -> 232 | FE11: =SUMIFS($DA11:$DZ11,$DA$8:$DZ$8,FE$7,$DA$7:$DZ$7,FE$8) -> 226 | FF11: =+FE11-FD11 -> -6 | FG11: =IFERROR(FF11/FD11,1) -> -0.025862069 | FI11: =SUMIFS($EB11:$FB11,$EB$8:$FB$8,FI$7,$EB$7:$FB$7,FI$8) -> 757 | FJ11: =SUMIFS($EB11:$FB11,$EB$8:$FB$8,FJ$7,$EB$7:$FB$7,FJ$8) -> 849 | FK11: =+FJ11-FI11 -> 92 | FL11: =IFERROR(FK11/FI11,1) -> 0.12153236
B12: AAZ | C12: TOTAL | D12: =+SUM(D9:D11) -> 15763 | E12: =+SUM(E9:E11) -> 13343 | F12: =SUM(F9:F11) -> -2420 | G12: =IF(F12=0,0,IF(D12=0,1,F12/D12)) -> -0.15352408 | H12: =SUM(H9:H11) -> 15763 | I12: =SUM(I9:I11) -> 13343 | J12: =SUM(J9:J11) -> -2420 | K12: =IF(J12=0,0,IF(H12=0,1,J12/H12)) -> -0.15352408 | L12: =+SUM(L9:L11) -> 13196 | M12: =+SUM(M9:M11) -> 11342 | N12: =SUM(N9:N11) -> -1854 | O12: =IF(N12=0,0,IF(L12=0,1,N12/L12)) -> -0.14049712 | P12: =SUM(P9:P11) -> 28959 | Q12: =SUM(Q9:Q11) -> 24685 | R12: =SUM(R9:R11) -> -4274 | S12: =IF(R12=0,0,IF(P12=0,1,R12/P12)) -> -0.14758797 | T12: =+SUM(T9:T11) -> 12016 | U12: =+SUM(U9:U11) -> 13149 | V12: =SUM(V9:V11) -> 1133 | W12: =IF(V12=0,0,IF(T12=0,1,V12/T12)) -> 0.094290945 | X12: =SUM(X9:X11) -> 40975 | Y12: =SUM(Y9:Y11) -> 37834 | Z12: =SUM(Z9:Z11) -> -3141 | AA12: =IF(Z12=0,0,IF(X12=0,1,Z12/X12)) -> -0.076656498 | AB12: =+SUM(AB9:AB11) -> 10937 | AC12: =+SUM(AC9:AC11) -> 13177 | AD12: =SUM(AD9:AD11) -> 2240 | AE12: =IF(AD12=0,0,IF(AB12=0,1,AD12/AB12)) -> 0.20480936 | AF12: =SUM(AF9:AF11) -> 51912 | AG12: =SUM(AG9:AG11) -> 51011 | AH12: =SUM(AH9:AH11) -> -901 | AI12: =IF(AH12=0,0,IF(AF12=0,1,AH12/AF12)) -> -0.017356295 | AJ12: =+SUM(AJ9:AJ11) -> 20107 | AK12: =+SUM(AK9:AK11) -> 23221 | AL12: =SUM(AL9:AL11) -> 3114 | AM12: =IF(AL12=0,0,IF(AJ12=0,1,AL12/AJ12)) -> 0.15487144 | AN12: =SUM(AN9:AN11) -> 72019 | AO12: =SUM(AO9:AO11) -> 74232 | AP12: =SUM(AP9:AP11) -> 2213 | AQ12: =IF(AP12=0,0,IF(AN12=0,1,AP12/AN12)) -> 0.030728002 | AR12: =+SUM(AR9:AR11) -> 30314 | AS12: =+SUM(AS9:AS11) -> 29839 | AT12: =SUM(AT9:AT11) -> -475 | AU12: =IF(AT12=0,0,IF(AR12=0,1,AT12/AR12)) -> -0.015669328 | AV12: =SUM(AV9:AV11) -> 102333 | AW12: =SUM(AW9:AW11) -> 104071 | AX12: =SUM(AX9:AX11) -> 1738 | AY12: =IF(AX12=0,0,IF(AV12=0,1,AX12/AV12)) -> 0.016983769 | AZ12: =+SUM(AZ9:AZ11) -> 26938 | BA12: =+SUM(BA9:BA11) -> 28579 | BB12: =SUM(BB9:BB11) -> 1641 | BC12: =IF(BB12=0,0,IF(AZ12=0,1,BB12/AZ12)) -> 0.060917663 | BD12: =SUM(BD9:BD11) -> 129271 | BE12: =SUM(BE9:BE11) -> 132650 | BF12: =SUM(BF9:BF11) -> 3379 | BG12: =IF(BF12=0,0,IF(BD12=0,1,BF12/BD12)) -> 0.026138887 | BH12: =+SUM(BH9:BH11) -> 26263 | BI12: =+SUM(BI9:BI11) -> 26602 | BJ12: =SUM(BJ9:BJ11) -> 339 | BK12: =IF(BJ12=0,0,IF(BH12=0,1,BJ12/BH12)) -> 0.012907893 | BL12: =SUM(BL9:BL11) -> 155534 | BM12: =SUM(BM9:BM11) -> 159252 | BN12: =SUM(BN9:BN11) -> 3718 | BO12: =IF(BN12=0,0,IF(BL12=0,1,BN12/BL12)) -> 0.023904741 | BP12: =+SUM(BP9:BP11) -> 19944 | BQ12: =+SUM(BQ9:BQ11) -> 0 | BR12: =SUM(BR9:BR11) -> -19944 | BS12: =IF(BR12=0,0,IF(BP12=0,1,BR12/BP12)) -> -1 | BT12: =SUM(BT9:BT11) -> 175478 | BU12: =SUM(BU9:BU11) -> 159252 | BV12: =SUM(BV9:BV11) -> -16226 | BW12: =IF(BV12=0,0,IF(BT12=0,1,BV12/BT12)) -> -0.092467432 | BX12: =+SUM(BX9:BX11) -> 15007 | BY12: =+SUM(BY9:BY11) -> 0 | BZ12: =SUM(BZ9:BZ11) -> -15007 | CA12: =IF(BZ12=0,0,IF(BX12=0,1,BZ12/BX12)) -> -1 | CB12: =SUM(CB9:CB11) -> 190485 | CC12: =SUM(CC9:CC11) -> 159252 | CD12: =SUM(CD9:CD11) -> -31233 | CE12: =IF(CD12=0,0,IF(CB12=0,1,CD12/CB12)) -> -0.16396567 | CF12: =+SUM(CF9:CF11) -> 13145 | CG12: =+SUM(CG9:CG11) -> 0 | CH12: =SUM(CH9:CH11) -> -13145 | CI12: =IF(CH12=0,0,IF(CF12=0,1,CH12/CF12)) -> -1 | CJ12: =SUM(CJ9:CJ11) -> 203630 | CK12: =SUM(CK9:CK11) -> 159252 | CL12: =SUM(CL9:CL11) -> -44378 | CM12: =IF(CL12=0,0,IF(CJ12=0,1,CL12/CJ12)) -> -0.21793449 | CN12: =+SUM(CN9:CN11) -> 14342 | CO12: =+SUM(CO9:CO11) -> 0 | CP12: =SUM(CP9:CP11) -> -14342 | CQ12: =IF(CP12=0,0,IF(CN12=0,1,CP12/CN12)) -> -1 | CR12: =SUM(CR9:CR11) -> 217972 | CS12: =SUM(CS9:CS11) -> 159252 | CT12: =SUM(CT9:CT11) -> -58720 | CU12: =IF(CT12=0,0,IF(CR12=0,1,CT12/CR12)) -> -0.2693924 | CY12: Total | DA12: =SUM(DA9:DA11) -> 15763 | DB12: =SUM(DB9:DB11) -> 13196 | DC12: =SUM(DC9:DC11) -> 12016 | DD12: =SUM(DD9:DD11) -> 10937 | DE12: =SUM(DE9:DE11) -> 20107 | DF12: =SUM(DF9:DF11) -> 30314 | DG12: =SUM(DG9:DG11) -> 26938 | DH12: =SUM(DH9:DH11) -> 26263 | ... DL12: =SUM(DL9:DL11) -> 14342 | DO12: =SUM(DO9:DO11) -> 13343 | DP12: =SUM(DP9:DP11) -> 11342 | DQ12: =SUM(DQ9:DQ11) -> 13149 | DR12: =SUM(DR9:DR11) -> 13177 | DS12: =SUM(DS9:DS11) -> 23221 | DT12: =SUM(DT9:DT11) -> 29839 | DU12: =SUM(DU9:DU11) -> 28579 | DV12: =SUM(DV9:DV11) -> 26602 | ... DZ12: =SUM(DZ9:DZ11) -> 0 | EB12: =SUM(DA12) -> 15763 | EC12: =SUM($DA12:DB12) -> 28959 | ED12: =SUM($DA12:DC12) -> 40975 | EE12: =SUM($DA12:DD12) -> 51912 | EF12: =SUM($DA12:DE12) -> 72019 | EG12: =SUM($DA12:DF12) -> 102333 | EH12: =SUM($DA12:DG12) -> 129271 | EI12: =SUM($DA12:DH12) -> 155534 | EJ12: =SUM($DA12:DI12) -> 175478 | ... EM12: =SUM($DA12:DL12) -> 217972 | EQ12: =SUM($DO12:DO12) -> 13343 | ER12: =SUM($DO12:DP12) -> 24685 | ES12: =SUM($DO12:DQ12) -> 37834 | ET12: =SUM($DO12:DR12) -> 51011 | EU12: =SUM($DO12:DS12) -> 74232 | EV12: =SUM($DO12:DT12) -> 104071 | EW12: =SUM($DO12:DU12) -> 132650 | EX12: =SUM($DO12:DV12) -> 159252 | ... FB12: =SUM($DO12:DZ12) -> 159252 | FD12: =SUMIFS($DA12:$DZ12,$DA$8:$DZ$8,FD$7,$DA$7:$DZ$7,FD$8) -> 26263 | FE12: =SUMIFS($DA12:$DZ12,$DA$8:$DZ$8,FE$7,$DA$7:$DZ$7,FE$8) -> 26602 | FF12: =+FE12-FD12 -> 339 | FG12: =IFERROR(FF12/FD12,1) -> 0.012907893 | FI12: =SUMIFS($EB12:$FB12,$EB$8:$FB$8,FI$7,$EB$7:$FB$7,FI$8) -> 155534 | FJ12: =SUMIFS($EB12:$FB12,$EB$8:$FB$8,FJ$7,$EB$7:$FB$7,FJ$8) -> 159252 | FK12: =+FJ12-FI12 -> 3718 | FL12: =IFERROR(FK12/FI12,1) -> 0.023904741
B14: AMB | C14: Passenger Cars | D14: =+DA14 -> 280098 | E14: =OFFSET(DA14,0,14,1,1) -> 244968 | F14: =SUM(E14-D14) -> -35130 | G14: =IF(F14=0,0,IF(D14=0,1,F14/D14)) -> -0.12542039 | H14: =SUMIF($D$6:G$6,H$5,$D14:G14) -> 280098 | I14: =SUMIF($D$6:H$6,I$5,$D14:H14) -> 244968 | J14: =SUM(I14-H14) -> -35130 | K14: =IF(J14=0,0,IF(H14=0,1,J14/H14)) -> -0.12542039 | L14: =+DB14 -> 244945 | M14: =OFFSET(DB14,0,14,1,1) -> 235909 | N14: =SUM(M14-L14) -> -9036 | O14: =IF(N14=0,0,IF(L14=0,1,N14/L14)) -> -0.036889914 | P14: =SUMIF($D$6:O$6,P$5,$D14:O14) -> 525043 | Q14: =SUMIF($D$6:P$6,Q$5,$D14:P14) -> 480877 | R14: =SUM(Q14-P14) -> -44166 | S14: =IF(R14=0,0,IF(P14=0,1,R14/P14)) -> -0.084118825 | T14: =+DC14 -> 289302 | U14: =OFFSET(DC14,0,14,1,1) -> 286467 | V14: =SUM(U14-T14) -> -2835 | W14: =IF(V14=0,0,IF(T14=0,1,V14/T14)) -> -0.0097994483 | X14: =SUMIF($D$6:W$6,X$5,$D14:W14) -> 814345 | Y14: =SUMIF($D$6:X$6,Y$5,$D14:X14) -> 767344 | Z14: =SUM(Y14-X14) -> -47001 | AA14: =IF(Z14=0,0,IF(X14=0,1,Z14/X14)) -> -0.057716324 | AB14: =+DD14 -> 269693 | AC14: =OFFSET(DD14,0,14,1,1) -> 287252 | AD14: =SUM(AC14-AB14) -> 17559 | AE14: =IF(AD14=0,0,IF(AB14=0,1,AD14/AB14)) -> 0.065107363 | AF14: =SUMIF($D$6:AE$6,AF$5,$D14:AE14) -> 1084038 | AG14: =SUMIF($D$6:AF$6,AG$5,$D14:AF14) -> 1054596 | AH14: =SUM(AG14-AF14) -> -29442 | AI14: =IF(AH14=0,0,IF(AF14=0,1,AH14/AF14)) -> -0.027159565 | AJ14: =+DE14 -> 305241 | AK14: =OFFSET(DE14,0,14,1,1) -> 344785 | AL14: =SUM(AK14-AJ14) -> 39544 | AM14: =IF(AL14=0,0,IF(AJ14=0,1,AL14/AJ14)) -> 0.12955009 | AN14: =SUMIF($D$6:AM$6,AN$5,$D14:AM14) -> 1389279 | AO14: =SUMIF($D$6:AN$6,AO$5,$D14:AN14) -> 1399381 | AP14: =SUM(AO14-AN14) -> 10102 | AQ14: =IF(AP14=0,0,IF(AN14=0,1,AP14/AN14)) -> 0.0072713976 | AR14: =+DF14 -> 303868 | AS14: =OFFSET(DF14,0,14,1,1) -> 335273 | AT14: =SUM(AS14-AR14) -> 31405 | AU14: =IF(AT14=0,0,IF(AR14=0,1,AT14/AR14)) -> 0.1033508 | AV14: =SUMIF($D$6:AU$6,AV$5,$D14:AU14) -> 1693147 | AW14: =SUMIF($D$6:AV$6,AW$5,$D14:AV14) -> 1734654 | AX14: =SUM(AW14-AV14) -> 41507 | AY14: =IF(AX14=0,0,IF(AV14=0,1,AX14/AV14)) -> 0.024514705 | AZ14: =+DG14 -> 329795 | BA14: =OFFSET(DG14,0,14,1,1) -> 332961 | BB14: =SUM(BA14-AZ14) -> 3166 | BC14: =IF(BB14=0,0,IF(AZ14=0,1,BB14/AZ14)) -> 0.009599903 | BD14: =SUMIF($D$6:BC$6,BD$5,$D14:BC14) -> 2022942 | BE14: =SUMIF($D$6:BD$6,BE$5,$D14:BD14) -> 2067615 | BF14: =SUM(BE14-BD14) -> 44673 | BG14: =IF(BF14=0,0,IF(BD14=0,1,BF14/BD14)) -> 0.022083184 | BH14: =+DH14 -> 344858 | BI14: =OFFSET(DH14,0,14,1,1) -> 195796 | BJ14: =SUM(BI14-BH14) -> -149062 | BK14: =IF(BJ14=0,0,IF(BH14=0,1,BJ14/BH14)) -> -0.43224168 | BL14: =SUMIF($D$6:BK$6,BL$5,$D14:BK14) -> 2367800 | BM14: =SUMIF($D$6:BL$6,BM$5,$D14:BL14) -> 2263411 | BN14: =SUM(BM14-BL14) -> -104389 | BO14: =IF(BN14=0,0,IF(BL14=0,1,BN14/BL14)) -> -0.044086916 | BP14: =+DI14 -> 299282 | BQ14: =OFFSET(DI14,0,14,1,1) -> 0 | BR14: =SUM(BQ14-BP14) -> -299282 | BS14: =IF(BR14=0,0,IF(BP14=0,1,BR14/BP14)) -> -1 | BT14: =SUMIF($D$6:BS$6,BT$5,$D14:BS14) -> 2667082 | BU14: =SUMIF($D$6:BT$6,BU$5,$D14:BT14) -> 2263411 | BV14: =SUM(BU14-BT14) -> -403671 | BW14: =IF(BV14=0,0,IF(BT14=0,1,BV14/BT14)) -> -0.15135305 | BX14: =+DJ14 -> 319794 | BY14: =OFFSET(DJ14,0,14,1,1) -> 0 | BZ14: =SUM(BY14-BX14) -> -319794 | CA14: =IF(BZ14=0,0,IF(BX14=0,1,BZ14/BX14)) -> -1 | CB14: =SUMIF($D$6:CA$6,CB$5,$D14:CA14) -> 2986876 | CC14: =SUMIF($D$6:CB$6,CC$5,$D14:CB14) -> 2263411 | CD14: =SUM(CC14-CB14) -> -723465 | CE14: =IF(CD14=0,0,IF(CB14=0,1,CD14/CB14)) -> -0.24221461 | CF14: =+DK14 -> 284480 | CG14: =OFFSET(DK14,0,14,1,1) -> 0 | CH14: =SUM(CG14-CF14) -> -284480 | CI14: =IF(CH14=0,0,IF(CF14=0,1,CH14/CF14)) -> -1 | CJ14: =SUMIF($D$6:CI$6,CJ$5,$D14:CI14) -> 3271356 | CK14: =SUMIF($D$6:CJ$6,CK$5,$D14:CJ14) -> 2263411 | CL14: =SUM(CK14-CJ14) -> -1007945 | CM14: =IF(CL14=0,0,IF(CJ14=0,1,CL14/CJ14)) -> -0.30811229 | CN14: =+DL14 -> 275952 | CO14: =OFFSET(DL14,0,14,1,1) -> 0 | CP14: =SUM(CO14-CN14) -> -275952 | CQ14: =IF(CP14=0,0,IF(CN14=0,1,CP14/CN14)) -> -1 | CR14: =SUMIF($D$6:CQ$6,CR$5,$D14:CQ14) -> 3547308 | CS14: =SUMIF($D$6:CR$6,CS$5,$D14:CR14) -> 2263411 | CT14: =SUM(CS14-CR14) -> -1283897 | CU14: =IF(CT14=0,0,IF(CR14=0,1,CT14/CR14)) -> -0.36193559 | CX14: Ambassador Bridge | CY14: Passenger Cars | DA14: =SUMIF(AMB!$A$118:$A$138,Traffic!DA$7,AMB!E$118:E$138) -> 280098 | DB14: =SUMIF(AMB!$A$118:$A$138,Traffic!DB$7,AMB!F$118:F$138) -> 244945 | DC14: =SUMIF(AMB!$A$118:$A$138,Traffic!DC$7,AMB!G$118:G$138) -> 289302 | DD14: =SUMIF(AMB!$A$118:$A$138,Traffic!DD$7,AMB!H$118:H$138) -> 269693 | DE14: =SUMIF(AMB!$A$118:$A$138,Traffic!DE$7,AMB!I$118:I$138) -> 305241 | DF14: =SUMIF(AMB!$A$118:$A$138,Traffic!DF$7,AMB!J$118:J$138) -> 303868 | DG14: =SUMIF(AMB!$A$118:$A$138,Traffic!DG$7,AMB!K$118:K$138) -> 329795 | DH14: =SUMIF(AMB!$A$118:$A$138,Traffic!DH$7,AMB!L$118:L$138) -> 344858 | ... DL14: =SUMIF(AMB!$A$118:$A$138,Traffic!DL$7,AMB!P$118:P$138) -> 275952 | DO14: =SUMIF(AMB!$A$118:$A$138,Traffic!DO$7,AMB!E$118:E$138) -> 244968 | DP14: =SUMIF(AMB!$A$118:$A$138,Traffic!DP$7,AMB!F$118:F$138) -> 235909 | DQ14: =SUMIF(AMB!$A$118:$A$138,Traffic!DQ$7,AMB!G$118:G$138) -> 286467 | DR14: =SUMIF(AMB!$A$118:$A$138,Traffic!DR$7,AMB!H$118:H$138) -> 287252 | DS14: =SUMIF(AMB!$A$118:$A$138,Traffic!DS$7,AMB!I$118:I$138) -> 344785 | DT14: =SUMIF(AMB!$A$118:$A$138,Traffic!DT$7,AMB!J$118:J$138) -> 335273 | DU14: =SUMIF(AMB!$A$118:$A$138,Traffic!DU$7,AMB!K$118:K$138) -> 332961 | DV14: =SUMIF(AMB!$A$118:$A$138,Traffic!DV$7,AMB!L$118:L$138) -> 195796 | ... DZ14: =SUMIF(AMB!$A$118:$A$138,Traffic!DZ$7,AMB!P$118:P$138) -> 0 | EB14: =SUM(DA14) -> 280098 | EC14: =SUM($DA14:DB14) -> 525043 | ED14: =SUM($DA14:DC14) -> 814345 | EE14: =SUM($DA14:DD14) -> 1084038 | EF14: =SUM($DA14:DE14) -> 1389279 | EG14: =SUM($DA14:DF14) -> 1693147 | EH14: =SUM($DA14:DG14) -> 2022942 | EI14: =SUM($DA14:DH14) -> 2367800 | EJ14: =SUM($DA14:DI14) -> 2667082 | ... EM14: =SUM($DA14:DL14) -> 3547308 | EQ14: =SUM($DO14:DO14) -> 244968 | ER14: =SUM($DO14:DP14) -> 480877 | ES14: =SUM($DO14:DQ14) -> 767344 | ET14: =SUM($DO14:DR14) -> 1054596 | EU14: =SUM($DO14:DS14) -> 1399381 | EV14: =SUM($DO14:DT14) -> 1734654 | EW14: =SUM($DO14:DU14) -> 2067615 | EX14: =SUM($DO14:DV14) -> 2263411 | ... FB14: =SUM($DO14:DZ14) -> 2263411 | FD14: =SUMIFS($DA14:$DZ14,$DA$8:$DZ$8,FD$7,$DA$7:$DZ$7,FD$8) -> 344858 | FE14: =SUMIFS($DA14:$DZ14,$DA$8:$DZ$8,FE$7,$DA$7:$DZ$7,FE$8) -> 195796 | FF14: =+FE14-FD14 -> -149062 | FG14: =IFERROR(FF14/FD14,1) -> -0.43224168 | FI14: =SUMIFS($EB14:$FB14,$EB$8:$FB$8,FI$7,$EB$7:$FB$7,FI$8) -> 2367800 | FJ14: =SUMIFS($EB14:$FB14,$EB$8:$FB$8,FJ$7,$EB$7:$FB$7,FJ$8) -> 2263411 | FK14: =+FJ14-FI14 -> -104389 | FL14: =IFERROR(FK14/FI14,1) -> -0.044086916
A15: =+CX16 -> Ambassador Bridge | B15: AMB | C15: Trucks | D15: =+DA15 -> 168258 | E15: =OFFSET(DA15,0,14,1,1) -> 137952 | F15: =SUM(E15-D15) -> -30306 | G15: =IF(F15=0,0,IF(D15=0,1,F15/D15)) -> -0.18011625 | H15: =SUMIF($D$6:G$6,H$5,$D15:G15) -> 168258 | I15: =SUMIF($D$6:H$6,I$5,$D15:H15) -> 137952 | J15: =SUM(I15-H15) -> -30306 | K15: =IF(J15=0,0,IF(H15=0,1,J15/H15)) -> -0.18011625 | L15: =+DB15 -> 153819 | M15: =OFFSET(DB15,0,14,1,1) -> 149040 | N15: =SUM(M15-L15) -> -4779 | O15: =IF(N15=0,0,IF(L15=0,1,N15/L15)) -> -0.031068984 | P15: =SUMIF($D$6:O$6,P$5,$D15:O15) -> 322077 | Q15: =SUMIF($D$6:P$6,Q$5,$D15:P15) -> 286992 | R15: =SUM(Q15-P15) -> -35085 | S15: =IF(R15=0,0,IF(P15=0,1,R15/P15)) -> -0.10893358 | T15: =+DC15 -> 174669 | U15: =OFFSET(DC15,0,14,1,1) -> 172552 | V15: =SUM(U15-T15) -> -2117 | W15: =IF(V15=0,0,IF(T15=0,1,V15/T15)) -> -0.012120067 | X15: =SUMIF($D$6:W$6,X$5,$D15:W15) -> 496746 | Y15: =SUMIF($D$6:X$6,Y$5,$D15:X15) -> 459544 | Z15: =SUM(Y15-X15) -> -37202 | AA15: =IF(Z15=0,0,IF(X15=0,1,Z15/X15)) -> -0.074891393 | AB15: =+DD15 -> 151164 | AC15: =OFFSET(DD15,0,14,1,1) -> 170732 | AD15: =SUM(AC15-AB15) -> 19568 | AE15: =IF(AD15=0,0,IF(AB15=0,1,AD15/AB15)) -> 0.12944881 | AF15: =SUMIF($D$6:AE$6,AF$5,$D15:AE15) -> 647910 | AG15: =SUMIF($D$6:AF$6,AG$5,$D15:AF15) -> 630276 | AH15: =SUM(AG15-AF15) -> -17634 | AI15: =IF(AH15=0,0,IF(AF15=0,1,AH15/AF15)) -> -0.027216743 | AJ15: =+DE15 -> 151949 | AK15: =OFFSET(DE15,0,14,1,1) -> 187938 | AL15: =SUM(AK15-AJ15) -> 35989 | AM15: =IF(AL15=0,0,IF(AJ15=0,1,AL15/AJ15)) -> 0.23684921 | AN15: =SUMIF($D$6:AM$6,AN$5,$D15:AM15) -> 799859 | AO15: =SUMIF($D$6:AN$6,AO$5,$D15:AN15) -> 818214 | AP15: =SUM(AO15-AN15) -> 18355 | AQ15: =IF(AP15=0,0,IF(AN15=0,1,AP15/AN15)) -> 0.022947795 | AR15: =+DF15 -> 147800 | AS15: =OFFSET(DF15,0,14,1,1) -> 200500 | AT15: =SUM(AS15-AR15) -> 52700 | AU15: =IF(AT15=0,0,IF(AR15=0,1,AT15/AR15)) -> 0.35656292 | AV15: =SUMIF($D$6:AU$6,AV$5,$D15:AU15) -> 947659 | AW15: =SUMIF($D$6:AV$6,AW$5,$D15:AV15) -> 1018714 | AX15: =SUM(AW15-AV15) -> 71055 | AY15: =IF(AX15=0,0,IF(AV15=0,1,AX15/AV15)) -> 0.074979502 | AZ15: =+DG15 -> 152468 | BA15: =OFFSET(DG15,0,14,1,1) -> 183543 | BB15: =SUM(BA15-AZ15) -> 31075 | BC15: =IF(BB15=0,0,IF(AZ15=0,1,BB15/AZ15)) -> 0.20381326 | BD15: =SUMIF($D$6:BC$6,BD$5,$D15:BC15) -> 1100127 | BE15: =SUMIF($D$6:BD$6,BE$5,$D15:BD15) -> 1202257 | BF15: =SUM(BE15-BD15) -> 102130 | BG15: =IF(BF15=0,0,IF(BD15=0,1,BF15/BD15)) -> 0.092834736 | BH15: =+DH15 -> 148086 | BI15: =OFFSET(DH15,0,14,1,1) -> 149649 | BJ15: =SUM(BI15-BH15) -> 1563 | BK15: =IF(BJ15=0,0,IF(BH15=0,1,BJ15/BH15)) -> 0.010554678 | BL15: =SUMIF($D$6:BK$6,BL$5,$D15:BK15) -> 1248213 | BM15: =SUMIF($D$6:BL$6,BM$5,$D15:BL15) -> 1351906 | BN15: =SUM(BM15-BL15) -> 103693 | BO15: =IF(BN15=0,0,IF(BL15=0,1,BN15/BL15)) -> 0.083073161 | BP15: =+DI15 -> 158929 | BQ15: =OFFSET(DI15,0,14,1,1) -> 0 | BR15: =SUM(BQ15-BP15) -> -158929 | BS15: =IF(BR15=0,0,IF(BP15=0,1,BR15/BP15)) -> -1 | BT15: =SUMIF($D$6:BS$6,BT$5,$D15:BS15) -> 1407142 | BU15: =SUMIF($D$6:BT$6,BU$5,$D15:BT15) -> 1351906 | BV15: =SUM(BU15-BT15) -> -55236 | BW15: =IF(BV15=0,0,IF(BT15=0,1,BV15/BT15)) -> -0.039254034 | BX15: =+DJ15 -> 167101 | BY15: =OFFSET(DJ15,0,14,1,1) -> 0 | BZ15: =SUM(BY15-BX15) -> -167101 | CA15: =IF(BZ15=0,0,IF(BX15=0,1,BZ15/BX15)) -> -1 | CB15: =SUMIF($D$6:CA$6,CB$5,$D15:CA15) -> 1574243 | CC15: =SUMIF($D$6:CB$6,CC$5,$D15:CB15) -> 1351906 | CD15: =SUM(CC15-CB15) -> -222337 | CE15: =IF(CD15=0,0,IF(CB15=0,1,CD15/CB15)) -> -0.14123423 | CF15: =+DK15 -> 144111 | CG15: =OFFSET(DK15,0,14,1,1) -> 0 | CH15: =SUM(CG15-CF15) -> -144111 | CI15: =IF(CH15=0,0,IF(CF15=0,1,CH15/CF15)) -> -1 | CJ15: =SUMIF($D$6:CI$6,CJ$5,$D15:CI15) -> 1718354 | CK15: =SUMIF($D$6:CJ$6,CK$5,$D15:CJ15) -> 1351906 | CL15: =SUM(CK15-CJ15) -> -366448 | CM15: =IF(CL15=0,0,IF(CJ15=0,1,CL15/CJ15)) -> -0.21325524 | CN15: =+DL15 -> 140470 | CO15: =OFFSET(DL15,0,14,1,1) -> 0 | CP15: =SUM(CO15-CN15) -> -140470 | CQ15: =IF(CP15=0,0,IF(CN15=0,1,CP15/CN15)) -> -1 | CR15: =SUMIF($D$6:CQ$6,CR$5,$D15:CQ15) -> 1858824 | CS15: =SUMIF($D$6:CR$6,CS$5,$D15:CR15) -> 1351906 | CT15: =SUM(CS15-CR15) -> -506918 | CU15: =IF(CT15=0,0,IF(CR15=0,1,CT15/CR15)) -> -0.27270898 | CX15: Ambassador Bridge | CY15: Trucks | DA15: =SUMIF(AMB!$A$141:$A$161,Traffic!DA$7,AMB!E$141:E$161) -> 168258 | DB15: =SUMIF(AMB!$A$141:$A$161,Traffic!DB$7,AMB!F$141:F$161) -> 153819 | DC15: =SUMIF(AMB!$A$141:$A$161,Traffic!DC$7,AMB!G$141:G$161) -> 174669 | DD15: =SUMIF(AMB!$A$141:$A$161,Traffic!DD$7,AMB!H$141:H$161) -> 151164 | DE15: =SUMIF(AMB!$A$141:$A$161,Traffic!DE$7,AMB!I$141:I$161) -> 151949 | DF15: =SUMIF(AMB!$A$141:$A$161,Traffic!DF$7,AMB!J$141:J$161) -> 147800 | DG15: =SUMIF(AMB!$A$141:$A$161,Traffic!DG$7,AMB!K$141:K$161) -> 152468 | DH15: =SUMIF(AMB!$A$141:$A$161,Traffic!DH$7,AMB!L$141:L$161) -> 148086 | ... DL15: =SUMIF(AMB!$A$141:$A$161,Traffic!DL$7,AMB!P$141:P$161) -> 140470 | DO15: =SUMIF(AMB!$A$141:$A$161,Traffic!DO$7,AMB!E$141:E$161) -> 137952 | DP15: =SUMIF(AMB!$A$141:$A$161,Traffic!DP$7,AMB!F$141:F$161) -> 149040 | DQ15: =SUMIF(AMB!$A$141:$A$161,Traffic!DQ$7,AMB!G$141:G$161) -> 172552 | DR15: =SUMIF(AMB!$A$141:$A$161,Traffic!DR$7,AMB!H$141:H$161) -> 170732 | DS15: =SUMIF(AMB!$A$141:$A$161,Traffic!DS$7,AMB!I$141:I$161) -> 187938 | DT15: =SUMIF(AMB!$A$141:$A$161,Traffic!DT$7,AMB!J$141:J$161) -> 200500 | DU15: =SUMIF(AMB!$A$141:$A$161,Traffic!DU$7,AMB!K$141:K$161) -> 183543 | DV15: =SUMIF(AMB!$A$141:$A$161,Traffic!DV$7,AMB!L$141:L$161) -> 149649 | ... DZ15: =SUMIF(AMB!$A$141:$A$161,Traffic!DZ$7,AMB!P$141:P$161) -> 0 | EB15: =SUM(DA15) -> 168258 | EC15: =SUM($DA15:DB15) -> 322077 | ED15: =SUM($DA15:DC15) -> 496746 | EE15: =SUM($DA15:DD15) -> 647910 | EF15: =SUM($DA15:DE15) -> 799859 | EG15: =SUM($DA15:DF15) -> 947659 | EH15: =SUM($DA15:DG15) -> 1100127 | EI15: =SUM($DA15:DH15) -> 1248213 | EJ15: =SUM($DA15:DI15) -> 1407142 | ... EM15: =SUM($DA15:DL15) -> 1858824 | EQ15: =SUM($DO15:DO15) -> 137952 | ER15: =SUM($DO15:DP15) -> 286992 | ES15: =SUM($DO15:DQ15) -> 459544 | ET15: =SUM($DO15:DR15) -> 630276 | EU15: =SUM($DO15:DS15) -> 818214 | EV15: =SUM($DO15:DT15) -> 1018714 | EW15: =SUM($DO15:DU15) -> 1202257 | EX15: =SUM($DO15:DV15) -> 1351906 | ... FB15: =SUM($DO15:DZ15) -> 1351906 | FD15: =SUMIFS($DA15:$DZ15,$DA$8:$DZ$8,FD$7,$DA$7:$DZ$7,FD$8) -> 148086 | FE15: =SUMIFS($DA15:$DZ15,$DA$8:$DZ$8,FE$7,$DA$7:$DZ$7,FE$8) -> 149649 | FF15: =+FE15-FD15 -> 1563 | FG15: =IFERROR(FF15/FD15,1) -> 0.010554678 | FI15: =SUMIFS($EB15:$FB15,$EB$8:$FB$8,FI$7,$EB$7:$FB$7,FI$8) -> 1248213 | FJ15: =SUMIFS($EB15:$FB15,$EB$8:$FB$8,FJ$7,$EB$7:$FB$7,FJ$8) -> 1351906 | FK15: =+FJ15-FI15 -> 103693 | FL15: =IFERROR(FK15/FI15,1) -> 0.083073161
